2019-12-12 03:51:24 [scrapy.utils.log] INFO: Scrapy 1.7.4 started (bot: spider_tophub)
2019-12-12 03:51:24 [scrapy.utils.log] INFO: Versions: lxml 4.4.1.0, libxml2 2.9.9, cssselect 1.1.0, parsel 1.5.2, w3lib 1.21.0, Twisted 19.7.0, Python 3.7.5 (default, Nov 23 2019, 05:59:34) - [GCC 8.3.0], pyOpenSSL 19.0.0 (OpenSSL 1.1.1d  10 Sep 2019), cryptography 2.8, Platform Linux-3.10.0-1062.1.2.el7.x86_64-x86_64-with-debian-10.2
2019-12-12 03:51:24 [scrapy.crawler] INFO: Overridden settings: {'BOT_NAME': 'spider_tophub', 'DOWNLOAD_DELAY': 1, 'LOG_FILE': 'logs/spider_tophub/sspai_remen/4388ec241c8e11ea9d990242ac190004.log', 'NEWSPIDER_MODULE': 'spider_tophub.spiders', 'ROBOTSTXT_OBEY': True, 'SPIDER_MODULES': ['spider_tophub.spiders'], 'USER_AGENT': 'Mozilla/5.0 (Windows NT 10.0; Win64; x64) AppleWebKit/537.36 (KHTML, like Gecko) Chrome/77.0.3865.120 Safari/537.36'}
2019-12-12 03:51:24 [scrapy.extensions.telnet] INFO: Telnet Password: f1f80287cc1cde27
2019-12-12 03:51:24 [scrapy.middleware] INFO: Enabled extensions:
['scrapy.extensions.corestats.CoreStats',
 'scrapy.extensions.telnet.TelnetConsole',
 'scrapy.extensions.memusage.MemoryUsage',
 'scrapy.extensions.logstats.LogStats']
2019-12-12 03:51:25 [scrapy.middleware] INFO: Enabled downloader middlewares:
['scrapy.downloadermiddlewares.robotstxt.RobotsTxtMiddleware',
 'scrapy.downloadermiddlewares.httpauth.HttpAuthMiddleware',
 'scrapy.downloadermiddlewares.downloadtimeout.DownloadTimeoutMiddleware',
 'scrapy.downloadermiddlewares.defaultheaders.DefaultHeadersMiddleware',
 'scrapy.downloadermiddlewares.useragent.UserAgentMiddleware',
 'scrapy.downloadermiddlewares.retry.RetryMiddleware',
 'scrapy.downloadermiddlewares.redirect.MetaRefreshMiddleware',
 'scrapy.downloadermiddlewares.httpcompression.HttpCompressionMiddleware',
 'scrapy.downloadermiddlewares.redirect.RedirectMiddleware',
 'scrapy.downloadermiddlewares.cookies.CookiesMiddleware',
 'scrapy.downloadermiddlewares.httpproxy.HttpProxyMiddleware',
 'scrapy.downloadermiddlewares.stats.DownloaderStats']
2019-12-12 03:51:25 [scrapy.middleware] INFO: Enabled spider middlewares:
['scrapy.spidermiddlewares.httperror.HttpErrorMiddleware',
 'scrapy.spidermiddlewares.offsite.OffsiteMiddleware',
 'scrapy.spidermiddlewares.referer.RefererMiddleware',
 'scrapy.spidermiddlewares.urllength.UrlLengthMiddleware',
 'scrapy.spidermiddlewares.depth.DepthMiddleware']
2019-12-12 03:51:25 [scrapy.middleware] INFO: Enabled item pipelines:
['spider_tophub.pipelines.MysqlTwistedPipeline']
2019-12-12 03:51:25 [scrapy.core.engine] INFO: Spider opened
2019-12-12 03:51:25 [scrapy.extensions.logstats] INFO: Crawled 0 pages (at 0 pages/min), scraped 0 items (at 0 items/min)
2019-12-12 03:51:25 [scrapy.extensions.telnet] INFO: Telnet console listening on 127.0.0.1:6023
2019-12-12 03:51:25 [scrapy.core.engine] DEBUG: Crawled (200) <GET https://sspai.com/robots.txt> (referer: None)
2019-12-12 03:51:27 [scrapy.core.engine] DEBUG: Crawled (200) <GET https://sspai.com/api/v1/articles?offset=0&limit=20&has_tag=1&tag=%E7%83%AD%E9%97%A8%E6%96%87%E7%AB%A0&include_total=false&type=recommend_to_home> (referer: None)
2019-12-12 03:51:27 [scrapy.core.scraper] DEBUG: Scraped from <200 https://sspai.com/api/v1/articles?offset=0&limit=20&has_tag=1&tag=%E7%83%AD%E9%97%A8%E6%96%87%E7%AB%A0&include_total=false&type=recommend_to_home>
None
2019-12-12 03:51:27 [scrapy.core.scraper] DEBUG: Scraped from <200 https://sspai.com/api/v1/articles?offset=0&limit=20&has_tag=1&tag=%E7%83%AD%E9%97%A8%E6%96%87%E7%AB%A0&include_total=false&type=recommend_to_home>
None
2019-12-12 03:51:27 [scrapy.core.scraper] DEBUG: Scraped from <200 https://sspai.com/api/v1/articles?offset=0&limit=20&has_tag=1&tag=%E7%83%AD%E9%97%A8%E6%96%87%E7%AB%A0&include_total=false&type=recommend_to_home>
None
2019-12-12 03:51:27 [scrapy.core.scraper] DEBUG: Scraped from <200 https://sspai.com/api/v1/articles?offset=0&limit=20&has_tag=1&tag=%E7%83%AD%E9%97%A8%E6%96%87%E7%AB%A0&include_total=false&type=recommend_to_home>
None
2019-12-12 03:51:27 [scrapy.core.scraper] DEBUG: Scraped from <200 https://sspai.com/api/v1/articles?offset=0&limit=20&has_tag=1&tag=%E7%83%AD%E9%97%A8%E6%96%87%E7%AB%A0&include_total=false&type=recommend_to_home>
None
2019-12-12 03:51:27 [scrapy.core.scraper] DEBUG: Scraped from <200 https://sspai.com/api/v1/articles?offset=0&limit=20&has_tag=1&tag=%E7%83%AD%E9%97%A8%E6%96%87%E7%AB%A0&include_total=false&type=recommend_to_home>
None
2019-12-12 03:51:27 [scrapy.core.scraper] DEBUG: Scraped from <200 https://sspai.com/api/v1/articles?offset=0&limit=20&has_tag=1&tag=%E7%83%AD%E9%97%A8%E6%96%87%E7%AB%A0&include_total=false&type=recommend_to_home>
None
2019-12-12 03:51:27 [scrapy.core.scraper] DEBUG: Scraped from <200 https://sspai.com/api/v1/articles?offset=0&limit=20&has_tag=1&tag=%E7%83%AD%E9%97%A8%E6%96%87%E7%AB%A0&include_total=false&type=recommend_to_home>
None
2019-12-12 03:51:27 [scrapy.core.scraper] DEBUG: Scraped from <200 https://sspai.com/api/v1/articles?offset=0&limit=20&has_tag=1&tag=%E7%83%AD%E9%97%A8%E6%96%87%E7%AB%A0&include_total=false&type=recommend_to_home>
None
2019-12-12 03:51:27 [scrapy.core.scraper] DEBUG: Scraped from <200 https://sspai.com/api/v1/articles?offset=0&limit=20&has_tag=1&tag=%E7%83%AD%E9%97%A8%E6%96%87%E7%AB%A0&include_total=false&type=recommend_to_home>
None
2019-12-12 03:51:27 [scrapy.core.scraper] DEBUG: Scraped from <200 https://sspai.com/api/v1/articles?offset=0&limit=20&has_tag=1&tag=%E7%83%AD%E9%97%A8%E6%96%87%E7%AB%A0&include_total=false&type=recommend_to_home>
None
2019-12-12 03:51:27 [scrapy.core.scraper] DEBUG: Scraped from <200 https://sspai.com/api/v1/articles?offset=0&limit=20&has_tag=1&tag=%E7%83%AD%E9%97%A8%E6%96%87%E7%AB%A0&include_total=false&type=recommend_to_home>
None
2019-12-12 03:51:27 [scrapy.core.scraper] DEBUG: Scraped from <200 https://sspai.com/api/v1/articles?offset=0&limit=20&has_tag=1&tag=%E7%83%AD%E9%97%A8%E6%96%87%E7%AB%A0&include_total=false&type=recommend_to_home>
None
2019-12-12 03:51:27 [scrapy.core.scraper] DEBUG: Scraped from <200 https://sspai.com/api/v1/articles?offset=0&limit=20&has_tag=1&tag=%E7%83%AD%E9%97%A8%E6%96%87%E7%AB%A0&include_total=false&type=recommend_to_home>
None
2019-12-12 03:51:27 [scrapy.core.scraper] DEBUG: Scraped from <200 https://sspai.com/api/v1/articles?offset=0&limit=20&has_tag=1&tag=%E7%83%AD%E9%97%A8%E6%96%87%E7%AB%A0&include_total=false&type=recommend_to_home>
None
2019-12-12 03:51:27 [scrapy.core.scraper] DEBUG: Scraped from <200 https://sspai.com/api/v1/articles?offset=0&limit=20&has_tag=1&tag=%E7%83%AD%E9%97%A8%E6%96%87%E7%AB%A0&include_total=false&type=recommend_to_home>
None
2019-12-12 03:51:27 [scrapy.core.scraper] DEBUG: Scraped from <200 https://sspai.com/api/v1/articles?offset=0&limit=20&has_tag=1&tag=%E7%83%AD%E9%97%A8%E6%96%87%E7%AB%A0&include_total=false&type=recommend_to_home>
None
2019-12-12 03:51:27 [scrapy.core.scraper] DEBUG: Scraped from <200 https://sspai.com/api/v1/articles?offset=0&limit=20&has_tag=1&tag=%E7%83%AD%E9%97%A8%E6%96%87%E7%AB%A0&include_total=false&type=recommend_to_home>
None
2019-12-12 03:51:27 [scrapy.core.scraper] DEBUG: Scraped from <200 https://sspai.com/api/v1/articles?offset=0&limit=20&has_tag=1&tag=%E7%83%AD%E9%97%A8%E6%96%87%E7%AB%A0&include_total=false&type=recommend_to_home>
None
2019-12-12 03:51:27 [scrapy.core.scraper] DEBUG: Scraped from <200 https://sspai.com/api/v1/articles?offset=0&limit=20&has_tag=1&tag=%E7%83%AD%E9%97%A8%E6%96%87%E7%AB%A0&include_total=false&type=recommend_to_home>
None
2019-12-12 03:51:27 [scrapy.core.engine] INFO: Closing spider (finished)
2019-12-12 03:51:27 [scrapy.statscollectors] INFO: Dumping Scrapy stats:
{'downloader/request_bytes': 715,
 'downloader/request_count': 2,
 'downloader/request_method_count/GET': 2,
 'downloader/response_bytes': 94773,
 'downloader/response_count': 2,
 'downloader/response_status_count/200': 2,
 'elapsed_time_seconds': 2.281475,
 'finish_reason': 'finished',
 'finish_time': datetime.datetime(2019, 12, 12, 3, 51, 27, 592821),
 'item_scraped_count': 20,
 'log_count/DEBUG': 22,
 'log_count/INFO': 10,
 'memusage/max': 57237504,
 'memusage/startup': 57237504,
 'response_received_count': 2,
 'robotstxt/request_count': 1,
 'robotstxt/response_count': 1,
 'robotstxt/response_status_count/200': 1,
 'scheduler/dequeued': 1,
 'scheduler/dequeued/memory': 1,
 'scheduler/enqueued': 1,
 'scheduler/enqueued/memory': 1,
 'start_time': datetime.datetime(2019, 12, 12, 3, 51, 25, 311346)}
2019-12-12 03:51:27 [scrapy.core.engine] INFO: Spider closed (finished)
2019-12-12 03:51:27 [urllib3.connectionpool] DEBUG: Starting new HTTP connection (1): elasticsearch:9200
2019-12-12 03:51:27 [urllib3.connectionpool] DEBUG: Starting new HTTP connection (1): elasticsearch:9200
2019-12-12 03:51:27 [urllib3.connectionpool] DEBUG: Starting new HTTP connection (1): elasticsearch:9200
2019-12-12 03:51:27 [urllib3.connectionpool] DEBUG: Starting new HTTP connection (1): elasticsearch:9200
2019-12-12 03:51:27 [elasticsearch] WARNING: HEAD http://elasticsearch:9200/top [status:N/A request:0.011s]
Traceback (most recent call last):
  File "/usr/local/lib/python3.7/site-packages/urllib3/connection.py", line 157, in _new_conn
    (self._dns_host, self.port), self.timeout, **extra_kw
  File "/usr/local/lib/python3.7/site-packages/urllib3/util/connection.py", line 84, in create_connection
    raise err
  File "/usr/local/lib/python3.7/site-packages/urllib3/util/connection.py", line 74, in create_connection
    sock.connect(sa)
ConnectionRefusedError: [Errno 111] Connection refused

During handling of the above exception, another exception occurred:

Traceback (most recent call last):
  File "/usr/local/lib/python3.7/site-packages/elasticsearch/connection/http_urllib3.py", line 238, in perform_request
    method, url, body, retries=Retry(False), headers=request_headers, **kw
  File "/usr/local/lib/python3.7/site-packages/urllib3/connectionpool.py", line 720, in urlopen
    method, url, error=e, _pool=self, _stacktrace=sys.exc_info()[2]
  File "/usr/local/lib/python3.7/site-packages/urllib3/util/retry.py", line 376, in increment
    raise six.reraise(type(error), error, _stacktrace)
  File "/usr/local/lib/python3.7/site-packages/urllib3/packages/six.py", line 735, in reraise
    raise value
  File "/usr/local/lib/python3.7/site-packages/urllib3/connectionpool.py", line 672, in urlopen
    chunked=chunked,
  File "/usr/local/lib/python3.7/site-packages/urllib3/connectionpool.py", line 387, in _make_request
    conn.request(method, url, **httplib_request_kw)
  File "/usr/local/lib/python3.7/http/client.py", line 1252, in request
    self._send_request(method, url, body, headers, encode_chunked)
  File "/usr/local/lib/python3.7/http/client.py", line 1298, in _send_request
    self.endheaders(body, encode_chunked=encode_chunked)
  File "/usr/local/lib/python3.7/http/client.py", line 1247, in endheaders
    self._send_output(message_body, encode_chunked=encode_chunked)
  File "/usr/local/lib/python3.7/http/client.py", line 1026, in _send_output
    self.send(msg)
  File "/usr/local/lib/python3.7/http/client.py", line 966, in send
    self.connect()
  File "/usr/local/lib/python3.7/site-packages/urllib3/connection.py", line 184, in connect
    conn = self._new_conn()
  File "/usr/local/lib/python3.7/site-packages/urllib3/connection.py", line 169, in _new_conn
    self, "Failed to establish a new connection: %s" % e
urllib3.exceptions.NewConnectionError: <urllib3.connection.HTTPConnection object at 0x7efc24602350>: Failed to establish a new connection: [Errno 111] Connection refused
2019-12-12 03:51:27 [elasticsearch] DEBUG: > None
2019-12-12 03:51:27 [urllib3.connectionpool] DEBUG: Starting new HTTP connection (2): elasticsearch:9200
2019-12-12 03:51:27 [urllib3.connectionpool] DEBUG: Starting new HTTP connection (1): elasticsearch:9200
2019-12-12 03:51:27 [elasticsearch] WARNING: HEAD http://elasticsearch:9200/top [status:N/A request:0.016s]
Traceback (most recent call last):
  File "/usr/local/lib/python3.7/site-packages/urllib3/connection.py", line 157, in _new_conn
    (self._dns_host, self.port), self.timeout, **extra_kw
  File "/usr/local/lib/python3.7/site-packages/urllib3/util/connection.py", line 84, in create_connection
    raise err
  File "/usr/local/lib/python3.7/site-packages/urllib3/util/connection.py", line 74, in create_connection
    sock.connect(sa)
ConnectionRefusedError: [Errno 111] Connection refused

During handling of the above exception, another exception occurred:

Traceback (most recent call last):
  File "/usr/local/lib/python3.7/site-packages/elasticsearch/connection/http_urllib3.py", line 238, in perform_request
    method, url, body, retries=Retry(False), headers=request_headers, **kw
  File "/usr/local/lib/python3.7/site-packages/urllib3/connectionpool.py", line 720, in urlopen
    method, url, error=e, _pool=self, _stacktrace=sys.exc_info()[2]
  File "/usr/local/lib/python3.7/site-packages/urllib3/util/retry.py", line 376, in increment
    raise six.reraise(type(error), error, _stacktrace)
  File "/usr/local/lib/python3.7/site-packages/urllib3/packages/six.py", line 735, in reraise
    raise value
  File "/usr/local/lib/python3.7/site-packages/urllib3/connectionpool.py", line 672, in urlopen
    chunked=chunked,
  File "/usr/local/lib/python3.7/site-packages/urllib3/connectionpool.py", line 387, in _make_request
    conn.request(method, url, **httplib_request_kw)
  File "/usr/local/lib/python3.7/http/client.py", line 1252, in request
    self._send_request(method, url, body, headers, encode_chunked)
  File "/usr/local/lib/python3.7/http/client.py", line 1298, in _send_request
    self.endheaders(body, encode_chunked=encode_chunked)
  File "/usr/local/lib/python3.7/http/client.py", line 1247, in endheaders
    self._send_output(message_body, encode_chunked=encode_chunked)
  File "/usr/local/lib/python3.7/http/client.py", line 1026, in _send_output
    self.send(msg)
  File "/usr/local/lib/python3.7/http/client.py", line 966, in send
    self.connect()
  File "/usr/local/lib/python3.7/site-packages/urllib3/connection.py", line 184, in connect
    conn = self._new_conn()
  File "/usr/local/lib/python3.7/site-packages/urllib3/connection.py", line 169, in _new_conn
    self, "Failed to establish a new connection: %s" % e
urllib3.exceptions.NewConnectionError: <urllib3.connection.HTTPConnection object at 0x7efc245ff690>: Failed to establish a new connection: [Errno 111] Connection refused
2019-12-12 03:51:27 [elasticsearch] DEBUG: > None
2019-12-12 03:51:27 [urllib3.connectionpool] DEBUG: Starting new HTTP connection (2): elasticsearch:9200
2019-12-12 03:51:27 [elasticsearch] WARNING: HEAD http://elasticsearch:9200/top [status:N/A request:0.018s]
Traceback (most recent call last):
  File "/usr/local/lib/python3.7/site-packages/urllib3/connection.py", line 157, in _new_conn
    (self._dns_host, self.port), self.timeout, **extra_kw
  File "/usr/local/lib/python3.7/site-packages/urllib3/util/connection.py", line 84, in create_connection
    raise err
  File "/usr/local/lib/python3.7/site-packages/urllib3/util/connection.py", line 74, in create_connection
    sock.connect(sa)
ConnectionRefusedError: [Errno 111] Connection refused

During handling of the above exception, another exception occurred:

Traceback (most recent call last):
  File "/usr/local/lib/python3.7/site-packages/elasticsearch/connection/http_urllib3.py", line 238, in perform_request
    method, url, body, retries=Retry(False), headers=request_headers, **kw
  File "/usr/local/lib/python3.7/site-packages/urllib3/connectionpool.py", line 720, in urlopen
    method, url, error=e, _pool=self, _stacktrace=sys.exc_info()[2]
  File "/usr/local/lib/python3.7/site-packages/urllib3/util/retry.py", line 376, in increment
    raise six.reraise(type(error), error, _stacktrace)
  File "/usr/local/lib/python3.7/site-packages/urllib3/packages/six.py", line 735, in reraise
    raise value
  File "/usr/local/lib/python3.7/site-packages/urllib3/connectionpool.py", line 672, in urlopen
    chunked=chunked,
  File "/usr/local/lib/python3.7/site-packages/urllib3/connectionpool.py", line 387, in _make_request
    conn.request(method, url, **httplib_request_kw)
  File "/usr/local/lib/python3.7/http/client.py", line 1252, in request
    self._send_request(method, url, body, headers, encode_chunked)
  File "/usr/local/lib/python3.7/http/client.py", line 1298, in _send_request
    self.endheaders(body, encode_chunked=encode_chunked)
  File "/usr/local/lib/python3.7/http/client.py", line 1247, in endheaders
    self._send_output(message_body, encode_chunked=encode_chunked)
  File "/usr/local/lib/python3.7/http/client.py", line 1026, in _send_output
    self.send(msg)
  File "/usr/local/lib/python3.7/http/client.py", line 966, in send
    self.connect()
  File "/usr/local/lib/python3.7/site-packages/urllib3/connection.py", line 184, in connect
    conn = self._new_conn()
  File "/usr/local/lib/python3.7/site-packages/urllib3/connection.py", line 169, in _new_conn
    self, "Failed to establish a new connection: %s" % e
urllib3.exceptions.NewConnectionError: <urllib3.connection.HTTPConnection object at 0x7efc25f0c310>: Failed to establish a new connection: [Errno 111] Connection refused
2019-12-12 03:51:27 [elasticsearch] DEBUG: > None
2019-12-12 03:51:27 [urllib3.connectionpool] DEBUG: Starting new HTTP connection (2): elasticsearch:9200
2019-12-12 03:51:27 [elasticsearch] WARNING: HEAD http://elasticsearch:9200/top [status:N/A request:0.015s]
Traceback (most recent call last):
  File "/usr/local/lib/python3.7/site-packages/urllib3/connection.py", line 157, in _new_conn
    (self._dns_host, self.port), self.timeout, **extra_kw
  File "/usr/local/lib/python3.7/site-packages/urllib3/util/connection.py", line 84, in create_connection
    raise err
  File "/usr/local/lib/python3.7/site-packages/urllib3/util/connection.py", line 74, in create_connection
    sock.connect(sa)
ConnectionRefusedError: [Errno 111] Connection refused

During handling of the above exception, another exception occurred:

Traceback (most recent call last):
  File "/usr/local/lib/python3.7/site-packages/elasticsearch/connection/http_urllib3.py", line 238, in perform_request
    method, url, body, retries=Retry(False), headers=request_headers, **kw
  File "/usr/local/lib/python3.7/site-packages/urllib3/connectionpool.py", line 720, in urlopen
    method, url, error=e, _pool=self, _stacktrace=sys.exc_info()[2]
  File "/usr/local/lib/python3.7/site-packages/urllib3/util/retry.py", line 376, in increment
    raise six.reraise(type(error), error, _stacktrace)
  File "/usr/local/lib/python3.7/site-packages/urllib3/packages/six.py", line 735, in reraise
    raise value
  File "/usr/local/lib/python3.7/site-packages/urllib3/connectionpool.py", line 672, in urlopen
    chunked=chunked,
  File "/usr/local/lib/python3.7/site-packages/urllib3/connectionpool.py", line 387, in _make_request
    conn.request(method, url, **httplib_request_kw)
  File "/usr/local/lib/python3.7/http/client.py", line 1252, in request
    self._send_request(method, url, body, headers, encode_chunked)
  File "/usr/local/lib/python3.7/http/client.py", line 1298, in _send_request
    self.endheaders(body, encode_chunked=encode_chunked)
  File "/usr/local/lib/python3.7/http/client.py", line 1247, in endheaders
    self._send_output(message_body, encode_chunked=encode_chunked)
  File "/usr/local/lib/python3.7/http/client.py", line 1026, in _send_output
    self.send(msg)
  File "/usr/local/lib/python3.7/http/client.py", line 966, in send
    self.connect()
  File "/usr/local/lib/python3.7/site-packages/urllib3/connection.py", line 184, in connect
    conn = self._new_conn()
  File "/usr/local/lib/python3.7/site-packages/urllib3/connection.py", line 169, in _new_conn
    self, "Failed to establish a new connection: %s" % e
urllib3.exceptions.NewConnectionError: <urllib3.connection.HTTPConnection object at 0x7efc246a6f50>: Failed to establish a new connection: [Errno 111] Connection refused
2019-12-12 03:51:27 [elasticsearch] DEBUG: > None
2019-12-12 03:51:27 [urllib3.connectionpool] DEBUG: Starting new HTTP connection (2): elasticsearch:9200
2019-12-12 03:51:27 [elasticsearch] WARNING: HEAD http://elasticsearch:9200/top [status:N/A request:0.008s]
Traceback (most recent call last):
  File "/usr/local/lib/python3.7/site-packages/urllib3/connection.py", line 157, in _new_conn
    (self._dns_host, self.port), self.timeout, **extra_kw
  File "/usr/local/lib/python3.7/site-packages/urllib3/util/connection.py", line 84, in create_connection
    raise err
  File "/usr/local/lib/python3.7/site-packages/urllib3/util/connection.py", line 74, in create_connection
    sock.connect(sa)
ConnectionRefusedError: [Errno 111] Connection refused

During handling of the above exception, another exception occurred:

Traceback (most recent call last):
  File "/usr/local/lib/python3.7/site-packages/elasticsearch/connection/http_urllib3.py", line 238, in perform_request
    method, url, body, retries=Retry(False), headers=request_headers, **kw
  File "/usr/local/lib/python3.7/site-packages/urllib3/connectionpool.py", line 720, in urlopen
    method, url, error=e, _pool=self, _stacktrace=sys.exc_info()[2]
  File "/usr/local/lib/python3.7/site-packages/urllib3/util/retry.py", line 376, in increment
    raise six.reraise(type(error), error, _stacktrace)
  File "/usr/local/lib/python3.7/site-packages/urllib3/packages/six.py", line 735, in reraise
    raise value
  File "/usr/local/lib/python3.7/site-packages/urllib3/connectionpool.py", line 672, in urlopen
    chunked=chunked,
  File "/usr/local/lib/python3.7/site-packages/urllib3/connectionpool.py", line 387, in _make_request
    conn.request(method, url, **httplib_request_kw)
  File "/usr/local/lib/python3.7/http/client.py", line 1252, in request
    self._send_request(method, url, body, headers, encode_chunked)
  File "/usr/local/lib/python3.7/http/client.py", line 1298, in _send_request
    self.endheaders(body, encode_chunked=encode_chunked)
  File "/usr/local/lib/python3.7/http/client.py", line 1247, in endheaders
    self._send_output(message_body, encode_chunked=encode_chunked)
  File "/usr/local/lib/python3.7/http/client.py", line 1026, in _send_output
    self.send(msg)
  File "/usr/local/lib/python3.7/http/client.py", line 966, in send
    self.connect()
  File "/usr/local/lib/python3.7/site-packages/urllib3/connection.py", line 184, in connect
    conn = self._new_conn()
  File "/usr/local/lib/python3.7/site-packages/urllib3/connection.py", line 169, in _new_conn
    self, "Failed to establish a new connection: %s" % e
urllib3.exceptions.NewConnectionError: <urllib3.connection.HTTPConnection object at 0x7efc245800d0>: Failed to establish a new connection: [Errno 111] Connection refused
2019-12-12 03:51:27 [elasticsearch] DEBUG: > None
2019-12-12 03:51:27 [urllib3.connectionpool] DEBUG: Starting new HTTP connection (2): elasticsearch:9200
2019-12-12 03:51:27 [elasticsearch] WARNING: HEAD http://elasticsearch:9200/top [status:N/A request:0.007s]
Traceback (most recent call last):
  File "/usr/local/lib/python3.7/site-packages/urllib3/connection.py", line 157, in _new_conn
    (self._dns_host, self.port), self.timeout, **extra_kw
  File "/usr/local/lib/python3.7/site-packages/urllib3/util/connection.py", line 84, in create_connection
    raise err
  File "/usr/local/lib/python3.7/site-packages/urllib3/util/connection.py", line 74, in create_connection
    sock.connect(sa)
ConnectionRefusedError: [Errno 111] Connection refused

During handling of the above exception, another exception occurred:

Traceback (most recent call last):
  File "/usr/local/lib/python3.7/site-packages/elasticsearch/connection/http_urllib3.py", line 238, in perform_request
    method, url, body, retries=Retry(False), headers=request_headers, **kw
  File "/usr/local/lib/python3.7/site-packages/urllib3/connectionpool.py", line 720, in urlopen
    method, url, error=e, _pool=self, _stacktrace=sys.exc_info()[2]
  File "/usr/local/lib/python3.7/site-packages/urllib3/util/retry.py", line 376, in increment
    raise six.reraise(type(error), error, _stacktrace)
  File "/usr/local/lib/python3.7/site-packages/urllib3/packages/six.py", line 735, in reraise
    raise value
  File "/usr/local/lib/python3.7/site-packages/urllib3/connectionpool.py", line 672, in urlopen
    chunked=chunked,
  File "/usr/local/lib/python3.7/site-packages/urllib3/connectionpool.py", line 387, in _make_request
    conn.request(method, url, **httplib_request_kw)
  File "/usr/local/lib/python3.7/http/client.py", line 1252, in request
    self._send_request(method, url, body, headers, encode_chunked)
  File "/usr/local/lib/python3.7/http/client.py", line 1298, in _send_request
    self.endheaders(body, encode_chunked=encode_chunked)
  File "/usr/local/lib/python3.7/http/client.py", line 1247, in endheaders
    self._send_output(message_body, encode_chunked=encode_chunked)
  File "/usr/local/lib/python3.7/http/client.py", line 1026, in _send_output
    self.send(msg)
  File "/usr/local/lib/python3.7/http/client.py", line 966, in send
    self.connect()
  File "/usr/local/lib/python3.7/site-packages/urllib3/connection.py", line 184, in connect
    conn = self._new_conn()
  File "/usr/local/lib/python3.7/site-packages/urllib3/connection.py", line 169, in _new_conn
    self, "Failed to establish a new connection: %s" % e
urllib3.exceptions.NewConnectionError: <urllib3.connection.HTTPConnection object at 0x7efc24580250>: Failed to establish a new connection: [Errno 111] Connection refused
2019-12-12 03:51:27 [elasticsearch] DEBUG: > None
2019-12-12 03:51:27 [urllib3.connectionpool] DEBUG: Starting new HTTP connection (3): elasticsearch:9200
2019-12-12 03:51:27 [elasticsearch] WARNING: HEAD http://elasticsearch:9200/top [status:N/A request:0.007s]
Traceback (most recent call last):
  File "/usr/local/lib/python3.7/site-packages/urllib3/connection.py", line 157, in _new_conn
    (self._dns_host, self.port), self.timeout, **extra_kw
  File "/usr/local/lib/python3.7/site-packages/urllib3/util/connection.py", line 84, in create_connection
    raise err
  File "/usr/local/lib/python3.7/site-packages/urllib3/util/connection.py", line 74, in create_connection
    sock.connect(sa)
ConnectionRefusedError: [Errno 111] Connection refused

During handling of the above exception, another exception occurred:

Traceback (most recent call last):
  File "/usr/local/lib/python3.7/site-packages/elasticsearch/connection/http_urllib3.py", line 238, in perform_request
    method, url, body, retries=Retry(False), headers=request_headers, **kw
  File "/usr/local/lib/python3.7/site-packages/urllib3/connectionpool.py", line 720, in urlopen
    method, url, error=e, _pool=self, _stacktrace=sys.exc_info()[2]
  File "/usr/local/lib/python3.7/site-packages/urllib3/util/retry.py", line 376, in increment
    raise six.reraise(type(error), error, _stacktrace)
  File "/usr/local/lib/python3.7/site-packages/urllib3/packages/six.py", line 735, in reraise
    raise value
  File "/usr/local/lib/python3.7/site-packages/urllib3/connectionpool.py", line 672, in urlopen
    chunked=chunked,
  File "/usr/local/lib/python3.7/site-packages/urllib3/connectionpool.py", line 387, in _make_request
    conn.request(method, url, **httplib_request_kw)
  File "/usr/local/lib/python3.7/http/client.py", line 1252, in request
    self._send_request(method, url, body, headers, encode_chunked)
  File "/usr/local/lib/python3.7/http/client.py", line 1298, in _send_request
    self.endheaders(body, encode_chunked=encode_chunked)
  File "/usr/local/lib/python3.7/http/client.py", line 1247, in endheaders
    self._send_output(message_body, encode_chunked=encode_chunked)
  File "/usr/local/lib/python3.7/http/client.py", line 1026, in _send_output
    self.send(msg)
  File "/usr/local/lib/python3.7/http/client.py", line 966, in send
    self.connect()
  File "/usr/local/lib/python3.7/site-packages/urllib3/connection.py", line 184, in connect
    conn = self._new_conn()
  File "/usr/local/lib/python3.7/site-packages/urllib3/connection.py", line 169, in _new_conn
    self, "Failed to establish a new connection: %s" % e
urllib3.exceptions.NewConnectionError: <urllib3.connection.HTTPConnection object at 0x7efc24580510>: Failed to establish a new connection: [Errno 111] Connection refused
2019-12-12 03:51:27 [elasticsearch] DEBUG: > None
2019-12-12 03:51:27 [urllib3.connectionpool] DEBUG: Starting new HTTP connection (3): elasticsearch:9200
2019-12-12 03:51:27 [elasticsearch] WARNING: HEAD http://elasticsearch:9200/top [status:N/A request:0.007s]
Traceback (most recent call last):
  File "/usr/local/lib/python3.7/site-packages/urllib3/connection.py", line 157, in _new_conn
    (self._dns_host, self.port), self.timeout, **extra_kw
  File "/usr/local/lib/python3.7/site-packages/urllib3/util/connection.py", line 84, in create_connection
    raise err
  File "/usr/local/lib/python3.7/site-packages/urllib3/util/connection.py", line 74, in create_connection
    sock.connect(sa)
ConnectionRefusedError: [Errno 111] Connection refused

During handling of the above exception, another exception occurred:

Traceback (most recent call last):
  File "/usr/local/lib/python3.7/site-packages/elasticsearch/connection/http_urllib3.py", line 238, in perform_request
    method, url, body, retries=Retry(False), headers=request_headers, **kw
  File "/usr/local/lib/python3.7/site-packages/urllib3/connectionpool.py", line 720, in urlopen
    method, url, error=e, _pool=self, _stacktrace=sys.exc_info()[2]
  File "/usr/local/lib/python3.7/site-packages/urllib3/util/retry.py", line 376, in increment
    raise six.reraise(type(error), error, _stacktrace)
  File "/usr/local/lib/python3.7/site-packages/urllib3/packages/six.py", line 735, in reraise
    raise value
  File "/usr/local/lib/python3.7/site-packages/urllib3/connectionpool.py", line 672, in urlopen
    chunked=chunked,
  File "/usr/local/lib/python3.7/site-packages/urllib3/connectionpool.py", line 387, in _make_request
    conn.request(method, url, **httplib_request_kw)
  File "/usr/local/lib/python3.7/http/client.py", line 1252, in request
    self._send_request(method, url, body, headers, encode_chunked)
  File "/usr/local/lib/python3.7/http/client.py", line 1298, in _send_request
    self.endheaders(body, encode_chunked=encode_chunked)
  File "/usr/local/lib/python3.7/http/client.py", line 1247, in endheaders
    self._send_output(message_body, encode_chunked=encode_chunked)
  File "/usr/local/lib/python3.7/http/client.py", line 1026, in _send_output
    self.send(msg)
  File "/usr/local/lib/python3.7/http/client.py", line 966, in send
    self.connect()
  File "/usr/local/lib/python3.7/site-packages/urllib3/connection.py", line 184, in connect
    conn = self._new_conn()
  File "/usr/local/lib/python3.7/site-packages/urllib3/connection.py", line 169, in _new_conn
    self, "Failed to establish a new connection: %s" % e
urllib3.exceptions.NewConnectionError: <urllib3.connection.HTTPConnection object at 0x7efc24580790>: Failed to establish a new connection: [Errno 111] Connection refused
2019-12-12 03:51:27 [elasticsearch] DEBUG: > None
2019-12-12 03:51:27 [urllib3.connectionpool] DEBUG: Starting new HTTP connection (3): elasticsearch:9200
2019-12-12 03:51:27 [elasticsearch] WARNING: HEAD http://elasticsearch:9200/top [status:N/A request:0.012s]
Traceback (most recent call last):
  File "/usr/local/lib/python3.7/site-packages/urllib3/connection.py", line 157, in _new_conn
    (self._dns_host, self.port), self.timeout, **extra_kw
  File "/usr/local/lib/python3.7/site-packages/urllib3/util/connection.py", line 84, in create_connection
    raise err
  File "/usr/local/lib/python3.7/site-packages/urllib3/util/connection.py", line 74, in create_connection
    sock.connect(sa)
ConnectionRefusedError: [Errno 111] Connection refused

During handling of the above exception, another exception occurred:

Traceback (most recent call last):
  File "/usr/local/lib/python3.7/site-packages/elasticsearch/connection/http_urllib3.py", line 238, in perform_request
    method, url, body, retries=Retry(False), headers=request_headers, **kw
  File "/usr/local/lib/python3.7/site-packages/urllib3/connectionpool.py", line 720, in urlopen
    method, url, error=e, _pool=self, _stacktrace=sys.exc_info()[2]
  File "/usr/local/lib/python3.7/site-packages/urllib3/util/retry.py", line 376, in increment
    raise six.reraise(type(error), error, _stacktrace)
  File "/usr/local/lib/python3.7/site-packages/urllib3/packages/six.py", line 735, in reraise
    raise value
  File "/usr/local/lib/python3.7/site-packages/urllib3/connectionpool.py", line 672, in urlopen
    chunked=chunked,
  File "/usr/local/lib/python3.7/site-packages/urllib3/connectionpool.py", line 387, in _make_request
    conn.request(method, url, **httplib_request_kw)
  File "/usr/local/lib/python3.7/http/client.py", line 1252, in request
    self._send_request(method, url, body, headers, encode_chunked)
  File "/usr/local/lib/python3.7/http/client.py", line 1298, in _send_request
    self.endheaders(body, encode_chunked=encode_chunked)
  File "/usr/local/lib/python3.7/http/client.py", line 1247, in endheaders
    self._send_output(message_body, encode_chunked=encode_chunked)
  File "/usr/local/lib/python3.7/http/client.py", line 1026, in _send_output
    self.send(msg)
  File "/usr/local/lib/python3.7/http/client.py", line 966, in send
    self.connect()
  File "/usr/local/lib/python3.7/site-packages/urllib3/connection.py", line 184, in connect
    conn = self._new_conn()
  File "/usr/local/lib/python3.7/site-packages/urllib3/connection.py", line 169, in _new_conn
    self, "Failed to establish a new connection: %s" % e
urllib3.exceptions.NewConnectionError: <urllib3.connection.HTTPConnection object at 0x7efc25f0c890>: Failed to establish a new connection: [Errno 111] Connection refused
2019-12-12 03:51:27 [elasticsearch] DEBUG: > None
2019-12-12 03:51:27 [urllib3.connectionpool] DEBUG: Starting new HTTP connection (3): elasticsearch:9200
2019-12-12 03:51:27 [elasticsearch] WARNING: HEAD http://elasticsearch:9200/top [status:N/A request:0.009s]
Traceback (most recent call last):
  File "/usr/local/lib/python3.7/site-packages/urllib3/connection.py", line 157, in _new_conn
    (self._dns_host, self.port), self.timeout, **extra_kw
  File "/usr/local/lib/python3.7/site-packages/urllib3/util/connection.py", line 84, in create_connection
    raise err
  File "/usr/local/lib/python3.7/site-packages/urllib3/util/connection.py", line 74, in create_connection
    sock.connect(sa)
ConnectionRefusedError: [Errno 111] Connection refused

During handling of the above exception, another exception occurred:

Traceback (most recent call last):
  File "/usr/local/lib/python3.7/site-packages/elasticsearch/connection/http_urllib3.py", line 238, in perform_request
    method, url, body, retries=Retry(False), headers=request_headers, **kw
  File "/usr/local/lib/python3.7/site-packages/urllib3/connectionpool.py", line 720, in urlopen
    method, url, error=e, _pool=self, _stacktrace=sys.exc_info()[2]
  File "/usr/local/lib/python3.7/site-packages/urllib3/util/retry.py", line 376, in increment
    raise six.reraise(type(error), error, _stacktrace)
  File "/usr/local/lib/python3.7/site-packages/urllib3/packages/six.py", line 735, in reraise
    raise value
  File "/usr/local/lib/python3.7/site-packages/urllib3/connectionpool.py", line 672, in urlopen
    chunked=chunked,
  File "/usr/local/lib/python3.7/site-packages/urllib3/connectionpool.py", line 387, in _make_request
    conn.request(method, url, **httplib_request_kw)
  File "/usr/local/lib/python3.7/http/client.py", line 1252, in request
    self._send_request(method, url, body, headers, encode_chunked)
  File "/usr/local/lib/python3.7/http/client.py", line 1298, in _send_request
    self.endheaders(body, encode_chunked=encode_chunked)
  File "/usr/local/lib/python3.7/http/client.py", line 1247, in endheaders
    self._send_output(message_body, encode_chunked=encode_chunked)
  File "/usr/local/lib/python3.7/http/client.py", line 1026, in _send_output
    self.send(msg)
  File "/usr/local/lib/python3.7/http/client.py", line 966, in send
    self.connect()
  File "/usr/local/lib/python3.7/site-packages/urllib3/connection.py", line 184, in connect
    conn = self._new_conn()
  File "/usr/local/lib/python3.7/site-packages/urllib3/connection.py", line 169, in _new_conn
    self, "Failed to establish a new connection: %s" % e
urllib3.exceptions.NewConnectionError: <urllib3.connection.HTTPConnection object at 0x7efc24580a10>: Failed to establish a new connection: [Errno 111] Connection refused
2019-12-12 03:51:27 [elasticsearch] DEBUG: > None
2019-12-12 03:51:27 [urllib3.connectionpool] DEBUG: Starting new HTTP connection (3): elasticsearch:9200
2019-12-12 03:51:27 [elasticsearch] WARNING: HEAD http://elasticsearch:9200/top [status:N/A request:0.009s]
Traceback (most recent call last):
  File "/usr/local/lib/python3.7/site-packages/urllib3/connection.py", line 157, in _new_conn
    (self._dns_host, self.port), self.timeout, **extra_kw
  File "/usr/local/lib/python3.7/site-packages/urllib3/util/connection.py", line 84, in create_connection
    raise err
  File "/usr/local/lib/python3.7/site-packages/urllib3/util/connection.py", line 74, in create_connection
    sock.connect(sa)
ConnectionRefusedError: [Errno 111] Connection refused

During handling of the above exception, another exception occurred:

Traceback (most recent call last):
  File "/usr/local/lib/python3.7/site-packages/elasticsearch/connection/http_urllib3.py", line 238, in perform_request
    method, url, body, retries=Retry(False), headers=request_headers, **kw
  File "/usr/local/lib/python3.7/site-packages/urllib3/connectionpool.py", line 720, in urlopen
    method, url, error=e, _pool=self, _stacktrace=sys.exc_info()[2]
  File "/usr/local/lib/python3.7/site-packages/urllib3/util/retry.py", line 376, in increment
    raise six.reraise(type(error), error, _stacktrace)
  File "/usr/local/lib/python3.7/site-packages/urllib3/packages/six.py", line 735, in reraise
    raise value
  File "/usr/local/lib/python3.7/site-packages/urllib3/connectionpool.py", line 672, in urlopen
    chunked=chunked,
  File "/usr/local/lib/python3.7/site-packages/urllib3/connectionpool.py", line 387, in _make_request
    conn.request(method, url, **httplib_request_kw)
  File "/usr/local/lib/python3.7/http/client.py", line 1252, in request
    self._send_request(method, url, body, headers, encode_chunked)
  File "/usr/local/lib/python3.7/http/client.py", line 1298, in _send_request
    self.endheaders(body, encode_chunked=encode_chunked)
  File "/usr/local/lib/python3.7/http/client.py", line 1247, in endheaders
    self._send_output(message_body, encode_chunked=encode_chunked)
  File "/usr/local/lib/python3.7/http/client.py", line 1026, in _send_output
    self.send(msg)
  File "/usr/local/lib/python3.7/http/client.py", line 966, in send
    self.connect()
  File "/usr/local/lib/python3.7/site-packages/urllib3/connection.py", line 184, in connect
    conn = self._new_conn()
  File "/usr/local/lib/python3.7/site-packages/urllib3/connection.py", line 169, in _new_conn
    self, "Failed to establish a new connection: %s" % e
urllib3.exceptions.NewConnectionError: <urllib3.connection.HTTPConnection object at 0x7efc24580c90>: Failed to establish a new connection: [Errno 111] Connection refused
2019-12-12 03:51:27 [elasticsearch] DEBUG: > None
2019-12-12 03:51:27 [urllib3.connectionpool] DEBUG: Starting new HTTP connection (4): elasticsearch:9200
2019-12-12 03:51:27 [elasticsearch] WARNING: HEAD http://elasticsearch:9200/top [status:N/A request:0.009s]
Traceback (most recent call last):
  File "/usr/local/lib/python3.7/site-packages/urllib3/connection.py", line 157, in _new_conn
    (self._dns_host, self.port), self.timeout, **extra_kw
  File "/usr/local/lib/python3.7/site-packages/urllib3/util/connection.py", line 84, in create_connection
    raise err
  File "/usr/local/lib/python3.7/site-packages/urllib3/util/connection.py", line 74, in create_connection
    sock.connect(sa)
ConnectionRefusedError: [Errno 111] Connection refused

During handling of the above exception, another exception occurred:

Traceback (most recent call last):
  File "/usr/local/lib/python3.7/site-packages/elasticsearch/connection/http_urllib3.py", line 238, in perform_request
    method, url, body, retries=Retry(False), headers=request_headers, **kw
  File "/usr/local/lib/python3.7/site-packages/urllib3/connectionpool.py", line 720, in urlopen
    method, url, error=e, _pool=self, _stacktrace=sys.exc_info()[2]
  File "/usr/local/lib/python3.7/site-packages/urllib3/util/retry.py", line 376, in increment
    raise six.reraise(type(error), error, _stacktrace)
  File "/usr/local/lib/python3.7/site-packages/urllib3/packages/six.py", line 735, in reraise
    raise value
  File "/usr/local/lib/python3.7/site-packages/urllib3/connectionpool.py", line 672, in urlopen
    chunked=chunked,
  File "/usr/local/lib/python3.7/site-packages/urllib3/connectionpool.py", line 387, in _make_request
    conn.request(method, url, **httplib_request_kw)
  File "/usr/local/lib/python3.7/http/client.py", line 1252, in request
    self._send_request(method, url, body, headers, encode_chunked)
  File "/usr/local/lib/python3.7/http/client.py", line 1298, in _send_request
    self.endheaders(body, encode_chunked=encode_chunked)
  File "/usr/local/lib/python3.7/http/client.py", line 1247, in endheaders
    self._send_output(message_body, encode_chunked=encode_chunked)
  File "/usr/local/lib/python3.7/http/client.py", line 1026, in _send_output
    self.send(msg)
  File "/usr/local/lib/python3.7/http/client.py", line 966, in send
    self.connect()
  File "/usr/local/lib/python3.7/site-packages/urllib3/connection.py", line 184, in connect
    conn = self._new_conn()
  File "/usr/local/lib/python3.7/site-packages/urllib3/connection.py", line 169, in _new_conn
    self, "Failed to establish a new connection: %s" % e
urllib3.exceptions.NewConnectionError: <urllib3.connection.HTTPConnection object at 0x7efc24580f50>: Failed to establish a new connection: [Errno 111] Connection refused
2019-12-12 03:51:27 [elasticsearch] DEBUG: > None
2019-12-12 03:51:27 [urllib3.connectionpool] DEBUG: Starting new HTTP connection (4): elasticsearch:9200
2019-12-12 03:51:27 [elasticsearch] WARNING: HEAD http://elasticsearch:9200/top [status:N/A request:0.009s]
Traceback (most recent call last):
  File "/usr/local/lib/python3.7/site-packages/urllib3/connection.py", line 157, in _new_conn
    (self._dns_host, self.port), self.timeout, **extra_kw
  File "/usr/local/lib/python3.7/site-packages/urllib3/util/connection.py", line 84, in create_connection
    raise err
  File "/usr/local/lib/python3.7/site-packages/urllib3/util/connection.py", line 74, in create_connection
    sock.connect(sa)
ConnectionRefusedError: [Errno 111] Connection refused

During handling of the above exception, another exception occurred:

Traceback (most recent call last):
  File "/usr/local/lib/python3.7/site-packages/elasticsearch/connection/http_urllib3.py", line 238, in perform_request
    method, url, body, retries=Retry(False), headers=request_headers, **kw
  File "/usr/local/lib/python3.7/site-packages/urllib3/connectionpool.py", line 720, in urlopen
    method, url, error=e, _pool=self, _stacktrace=sys.exc_info()[2]
  File "/usr/local/lib/python3.7/site-packages/urllib3/util/retry.py", line 376, in increment
    raise six.reraise(type(error), error, _stacktrace)
  File "/usr/local/lib/python3.7/site-packages/urllib3/packages/six.py", line 735, in reraise
    raise value
  File "/usr/local/lib/python3.7/site-packages/urllib3/connectionpool.py", line 672, in urlopen
    chunked=chunked,
  File "/usr/local/lib/python3.7/site-packages/urllib3/connectionpool.py", line 387, in _make_request
    conn.request(method, url, **httplib_request_kw)
  File "/usr/local/lib/python3.7/http/client.py", line 1252, in request
    self._send_request(method, url, body, headers, encode_chunked)
  File "/usr/local/lib/python3.7/http/client.py", line 1298, in _send_request
    self.endheaders(body, encode_chunked=encode_chunked)
  File "/usr/local/lib/python3.7/http/client.py", line 1247, in endheaders
    self._send_output(message_body, encode_chunked=encode_chunked)
  File "/usr/local/lib/python3.7/http/client.py", line 1026, in _send_output
    self.send(msg)
  File "/usr/local/lib/python3.7/http/client.py", line 966, in send
    self.connect()
  File "/usr/local/lib/python3.7/site-packages/urllib3/connection.py", line 184, in connect
    conn = self._new_conn()
  File "/usr/local/lib/python3.7/site-packages/urllib3/connection.py", line 169, in _new_conn
    self, "Failed to establish a new connection: %s" % e
urllib3.exceptions.NewConnectionError: <urllib3.connection.HTTPConnection object at 0x7efc2458d190>: Failed to establish a new connection: [Errno 111] Connection refused
2019-12-12 03:51:27 [elasticsearch] DEBUG: > None
2019-12-12 03:51:27 [urllib3.connectionpool] DEBUG: Starting new HTTP connection (4): elasticsearch:9200
2019-12-12 03:51:27 [elasticsearch] WARNING: HEAD http://elasticsearch:9200/top [status:N/A request:0.009s]
Traceback (most recent call last):
  File "/usr/local/lib/python3.7/site-packages/urllib3/connection.py", line 157, in _new_conn
    (self._dns_host, self.port), self.timeout, **extra_kw
  File "/usr/local/lib/python3.7/site-packages/urllib3/util/connection.py", line 84, in create_connection
    raise err
  File "/usr/local/lib/python3.7/site-packages/urllib3/util/connection.py", line 74, in create_connection
    sock.connect(sa)
ConnectionRefusedError: [Errno 111] Connection refused

During handling of the above exception, another exception occurred:

Traceback (most recent call last):
  File "/usr/local/lib/python3.7/site-packages/elasticsearch/connection/http_urllib3.py", line 238, in perform_request
    method, url, body, retries=Retry(False), headers=request_headers, **kw
  File "/usr/local/lib/python3.7/site-packages/urllib3/connectionpool.py", line 720, in urlopen
    method, url, error=e, _pool=self, _stacktrace=sys.exc_info()[2]
  File "/usr/local/lib/python3.7/site-packages/urllib3/util/retry.py", line 376, in increment
    raise six.reraise(type(error), error, _stacktrace)
  File "/usr/local/lib/python3.7/site-packages/urllib3/packages/six.py", line 735, in reraise
    raise value
  File "/usr/local/lib/python3.7/site-packages/urllib3/connectionpool.py", line 672, in urlopen
    chunked=chunked,
  File "/usr/local/lib/python3.7/site-packages/urllib3/connectionpool.py", line 387, in _make_request
    conn.request(method, url, **httplib_request_kw)
  File "/usr/local/lib/python3.7/http/client.py", line 1252, in request
    self._send_request(method, url, body, headers, encode_chunked)
  File "/usr/local/lib/python3.7/http/client.py", line 1298, in _send_request
    self.endheaders(body, encode_chunked=encode_chunked)
  File "/usr/local/lib/python3.7/http/client.py", line 1247, in endheaders
    self._send_output(message_body, encode_chunked=encode_chunked)
  File "/usr/local/lib/python3.7/http/client.py", line 1026, in _send_output
    self.send(msg)
  File "/usr/local/lib/python3.7/http/client.py", line 966, in send
    self.connect()
  File "/usr/local/lib/python3.7/site-packages/urllib3/connection.py", line 184, in connect
    conn = self._new_conn()
  File "/usr/local/lib/python3.7/site-packages/urllib3/connection.py", line 169, in _new_conn
    self, "Failed to establish a new connection: %s" % e
urllib3.exceptions.NewConnectionError: <urllib3.connection.HTTPConnection object at 0x7efc245fd710>: Failed to establish a new connection: [Errno 111] Connection refused
2019-12-12 03:51:27 [elasticsearch] DEBUG: > None
2019-12-12 03:51:27 [urllib3.connectionpool] DEBUG: Starting new HTTP connection (4): elasticsearch:9200
2019-12-12 03:51:27 [elasticsearch] WARNING: HEAD http://elasticsearch:9200/top [status:N/A request:0.008s]
Traceback (most recent call last):
  File "/usr/local/lib/python3.7/site-packages/urllib3/connection.py", line 157, in _new_conn
    (self._dns_host, self.port), self.timeout, **extra_kw
  File "/usr/local/lib/python3.7/site-packages/urllib3/util/connection.py", line 84, in create_connection
    raise err
  File "/usr/local/lib/python3.7/site-packages/urllib3/util/connection.py", line 74, in create_connection
    sock.connect(sa)
ConnectionRefusedError: [Errno 111] Connection refused

During handling of the above exception, another exception occurred:

Traceback (most recent call last):
  File "/usr/local/lib/python3.7/site-packages/elasticsearch/connection/http_urllib3.py", line 238, in perform_request
    method, url, body, retries=Retry(False), headers=request_headers, **kw
  File "/usr/local/lib/python3.7/site-packages/urllib3/connectionpool.py", line 720, in urlopen
    method, url, error=e, _pool=self, _stacktrace=sys.exc_info()[2]
  File "/usr/local/lib/python3.7/site-packages/urllib3/util/retry.py", line 376, in increment
    raise six.reraise(type(error), error, _stacktrace)
  File "/usr/local/lib/python3.7/site-packages/urllib3/packages/six.py", line 735, in reraise
    raise value
  File "/usr/local/lib/python3.7/site-packages/urllib3/connectionpool.py", line 672, in urlopen
    chunked=chunked,
  File "/usr/local/lib/python3.7/site-packages/urllib3/connectionpool.py", line 387, in _make_request
    conn.request(method, url, **httplib_request_kw)
  File "/usr/local/lib/python3.7/http/client.py", line 1252, in request
    self._send_request(method, url, body, headers, encode_chunked)
  File "/usr/local/lib/python3.7/http/client.py", line 1298, in _send_request
    self.endheaders(body, encode_chunked=encode_chunked)
  File "/usr/local/lib/python3.7/http/client.py", line 1247, in endheaders
    self._send_output(message_body, encode_chunked=encode_chunked)
  File "/usr/local/lib/python3.7/http/client.py", line 1026, in _send_output
    self.send(msg)
  File "/usr/local/lib/python3.7/http/client.py", line 966, in send
    self.connect()
  File "/usr/local/lib/python3.7/site-packages/urllib3/connection.py", line 184, in connect
    conn = self._new_conn()
  File "/usr/local/lib/python3.7/site-packages/urllib3/connection.py", line 169, in _new_conn
    self, "Failed to establish a new connection: %s" % e
urllib3.exceptions.NewConnectionError: <urllib3.connection.HTTPConnection object at 0x7efc245ff090>: Failed to establish a new connection: [Errno 111] Connection refused
2019-12-12 03:51:27 [elasticsearch] DEBUG: > None
2019-12-12 03:51:27 [urllib3.connectionpool] DEBUG: Starting new HTTP connection (4): elasticsearch:9200
2019-12-12 03:51:27 [elasticsearch] WARNING: HEAD http://elasticsearch:9200/top [status:N/A request:0.009s]
Traceback (most recent call last):
  File "/usr/local/lib/python3.7/site-packages/urllib3/connection.py", line 157, in _new_conn
    (self._dns_host, self.port), self.timeout, **extra_kw
  File "/usr/local/lib/python3.7/site-packages/urllib3/util/connection.py", line 84, in create_connection
    raise err
  File "/usr/local/lib/python3.7/site-packages/urllib3/util/connection.py", line 74, in create_connection
    sock.connect(sa)
ConnectionRefusedError: [Errno 111] Connection refused

During handling of the above exception, another exception occurred:

Traceback (most recent call last):
  File "/usr/local/lib/python3.7/site-packages/elasticsearch/connection/http_urllib3.py", line 238, in perform_request
    method, url, body, retries=Retry(False), headers=request_headers, **kw
  File "/usr/local/lib/python3.7/site-packages/urllib3/connectionpool.py", line 720, in urlopen
    method, url, error=e, _pool=self, _stacktrace=sys.exc_info()[2]
  File "/usr/local/lib/python3.7/site-packages/urllib3/util/retry.py", line 376, in increment
    raise six.reraise(type(error), error, _stacktrace)
  File "/usr/local/lib/python3.7/site-packages/urllib3/packages/six.py", line 735, in reraise
    raise value
  File "/usr/local/lib/python3.7/site-packages/urllib3/connectionpool.py", line 672, in urlopen
    chunked=chunked,
  File "/usr/local/lib/python3.7/site-packages/urllib3/connectionpool.py", line 387, in _make_request
    conn.request(method, url, **httplib_request_kw)
  File "/usr/local/lib/python3.7/http/client.py", line 1252, in request
    self._send_request(method, url, body, headers, encode_chunked)
  File "/usr/local/lib/python3.7/http/client.py", line 1298, in _send_request
    self.endheaders(body, encode_chunked=encode_chunked)
  File "/usr/local/lib/python3.7/http/client.py", line 1247, in endheaders
    self._send_output(message_body, encode_chunked=encode_chunked)
  File "/usr/local/lib/python3.7/http/client.py", line 1026, in _send_output
    self.send(msg)
  File "/usr/local/lib/python3.7/http/client.py", line 966, in send
    self.connect()
  File "/usr/local/lib/python3.7/site-packages/urllib3/connection.py", line 184, in connect
    conn = self._new_conn()
  File "/usr/local/lib/python3.7/site-packages/urllib3/connection.py", line 169, in _new_conn
    self, "Failed to establish a new connection: %s" % e
urllib3.exceptions.NewConnectionError: <urllib3.connection.HTTPConnection object at 0x7efc245803d0>: Failed to establish a new connection: [Errno 111] Connection refused
2019-12-12 03:51:27 [elasticsearch] DEBUG: > None
2019-12-12 03:51:27 [elasticsearch] WARNING: HEAD http://elasticsearch:9200/top [status:N/A request:0.008s]
Traceback (most recent call last):
  File "/usr/local/lib/python3.7/site-packages/urllib3/connection.py", line 157, in _new_conn
    (self._dns_host, self.port), self.timeout, **extra_kw
  File "/usr/local/lib/python3.7/site-packages/urllib3/util/connection.py", line 84, in create_connection
    raise err
  File "/usr/local/lib/python3.7/site-packages/urllib3/util/connection.py", line 74, in create_connection
    sock.connect(sa)
ConnectionRefusedError: [Errno 111] Connection refused

During handling of the above exception, another exception occurred:

Traceback (most recent call last):
  File "/usr/local/lib/python3.7/site-packages/elasticsearch/connection/http_urllib3.py", line 238, in perform_request
    method, url, body, retries=Retry(False), headers=request_headers, **kw
  File "/usr/local/lib/python3.7/site-packages/urllib3/connectionpool.py", line 720, in urlopen
    method, url, error=e, _pool=self, _stacktrace=sys.exc_info()[2]
  File "/usr/local/lib/python3.7/site-packages/urllib3/util/retry.py", line 376, in increment
    raise six.reraise(type(error), error, _stacktrace)
  File "/usr/local/lib/python3.7/site-packages/urllib3/packages/six.py", line 735, in reraise
    raise value
  File "/usr/local/lib/python3.7/site-packages/urllib3/connectionpool.py", line 672, in urlopen
    chunked=chunked,
  File "/usr/local/lib/python3.7/site-packages/urllib3/connectionpool.py", line 387, in _make_request
    conn.request(method, url, **httplib_request_kw)
  File "/usr/local/lib/python3.7/http/client.py", line 1252, in request
    self._send_request(method, url, body, headers, encode_chunked)
  File "/usr/local/lib/python3.7/http/client.py", line 1298, in _send_request
    self.endheaders(body, encode_chunked=encode_chunked)
  File "/usr/local/lib/python3.7/http/client.py", line 1247, in endheaders
    self._send_output(message_body, encode_chunked=encode_chunked)
  File "/usr/local/lib/python3.7/http/client.py", line 1026, in _send_output
    self.send(msg)
  File "/usr/local/lib/python3.7/http/client.py", line 966, in send
    self.connect()
  File "/usr/local/lib/python3.7/site-packages/urllib3/connection.py", line 184, in connect
    conn = self._new_conn()
  File "/usr/local/lib/python3.7/site-packages/urllib3/connection.py", line 169, in _new_conn
    self, "Failed to establish a new connection: %s" % e
urllib3.exceptions.NewConnectionError: <urllib3.connection.HTTPConnection object at 0x7efc24580250>: Failed to establish a new connection: [Errno 111] Connection refused
2019-12-12 03:51:27 [elasticsearch] DEBUG: > None
2019-12-12 03:51:27 [elasticsearch] WARNING: HEAD http://elasticsearch:9200/top [status:N/A request:0.008s]
Traceback (most recent call last):
  File "/usr/local/lib/python3.7/site-packages/urllib3/connection.py", line 157, in _new_conn
    (self._dns_host, self.port), self.timeout, **extra_kw
  File "/usr/local/lib/python3.7/site-packages/urllib3/util/connection.py", line 84, in create_connection
    raise err
  File "/usr/local/lib/python3.7/site-packages/urllib3/util/connection.py", line 74, in create_connection
    sock.connect(sa)
ConnectionRefusedError: [Errno 111] Connection refused

During handling of the above exception, another exception occurred:

Traceback (most recent call last):
  File "/usr/local/lib/python3.7/site-packages/elasticsearch/connection/http_urllib3.py", line 238, in perform_request
    method, url, body, retries=Retry(False), headers=request_headers, **kw
  File "/usr/local/lib/python3.7/site-packages/urllib3/connectionpool.py", line 720, in urlopen
    method, url, error=e, _pool=self, _stacktrace=sys.exc_info()[2]
  File "/usr/local/lib/python3.7/site-packages/urllib3/util/retry.py", line 376, in increment
    raise six.reraise(type(error), error, _stacktrace)
  File "/usr/local/lib/python3.7/site-packages/urllib3/packages/six.py", line 735, in reraise
    raise value
  File "/usr/local/lib/python3.7/site-packages/urllib3/connectionpool.py", line 672, in urlopen
    chunked=chunked,
  File "/usr/local/lib/python3.7/site-packages/urllib3/connectionpool.py", line 387, in _make_request
    conn.request(method, url, **httplib_request_kw)
  File "/usr/local/lib/python3.7/http/client.py", line 1252, in request
    self._send_request(method, url, body, headers, encode_chunked)
  File "/usr/local/lib/python3.7/http/client.py", line 1298, in _send_request
    self.endheaders(body, encode_chunked=encode_chunked)
  File "/usr/local/lib/python3.7/http/client.py", line 1247, in endheaders
    self._send_output(message_body, encode_chunked=encode_chunked)
  File "/usr/local/lib/python3.7/http/client.py", line 1026, in _send_output
    self.send(msg)
  File "/usr/local/lib/python3.7/http/client.py", line 966, in send
    self.connect()
  File "/usr/local/lib/python3.7/site-packages/urllib3/connection.py", line 184, in connect
    conn = self._new_conn()
  File "/usr/local/lib/python3.7/site-packages/urllib3/connection.py", line 169, in _new_conn
    self, "Failed to establish a new connection: %s" % e
urllib3.exceptions.NewConnectionError: <urllib3.connection.HTTPConnection object at 0x7efc245807d0>: Failed to establish a new connection: [Errno 111] Connection refused
2019-12-12 03:51:27 [elasticsearch] DEBUG: > None
2019-12-12 03:51:27 [elasticsearch] WARNING: HEAD http://elasticsearch:9200/top [status:N/A request:0.008s]
Traceback (most recent call last):
  File "/usr/local/lib/python3.7/site-packages/urllib3/connection.py", line 157, in _new_conn
    (self._dns_host, self.port), self.timeout, **extra_kw
  File "/usr/local/lib/python3.7/site-packages/urllib3/util/connection.py", line 84, in create_connection
    raise err
  File "/usr/local/lib/python3.7/site-packages/urllib3/util/connection.py", line 74, in create_connection
    sock.connect(sa)
ConnectionRefusedError: [Errno 111] Connection refused

During handling of the above exception, another exception occurred:

Traceback (most recent call last):
  File "/usr/local/lib/python3.7/site-packages/elasticsearch/connection/http_urllib3.py", line 238, in perform_request
    method, url, body, retries=Retry(False), headers=request_headers, **kw
  File "/usr/local/lib/python3.7/site-packages/urllib3/connectionpool.py", line 720, in urlopen
    method, url, error=e, _pool=self, _stacktrace=sys.exc_info()[2]
  File "/usr/local/lib/python3.7/site-packages/urllib3/util/retry.py", line 376, in increment
    raise six.reraise(type(error), error, _stacktrace)
  File "/usr/local/lib/python3.7/site-packages/urllib3/packages/six.py", line 735, in reraise
    raise value
  File "/usr/local/lib/python3.7/site-packages/urllib3/connectionpool.py", line 672, in urlopen
    chunked=chunked,
  File "/usr/local/lib/python3.7/site-packages/urllib3/connectionpool.py", line 387, in _make_request
    conn.request(method, url, **httplib_request_kw)
  File "/usr/local/lib/python3.7/http/client.py", line 1252, in request
    self._send_request(method, url, body, headers, encode_chunked)
  File "/usr/local/lib/python3.7/http/client.py", line 1298, in _send_request
    self.endheaders(body, encode_chunked=encode_chunked)
  File "/usr/local/lib/python3.7/http/client.py", line 1247, in endheaders
    self._send_output(message_body, encode_chunked=encode_chunked)
  File "/usr/local/lib/python3.7/http/client.py", line 1026, in _send_output
    self.send(msg)
  File "/usr/local/lib/python3.7/http/client.py", line 966, in send
    self.connect()
  File "/usr/local/lib/python3.7/site-packages/urllib3/connection.py", line 184, in connect
    conn = self._new_conn()
  File "/usr/local/lib/python3.7/site-packages/urllib3/connection.py", line 169, in _new_conn
    self, "Failed to establish a new connection: %s" % e
urllib3.exceptions.NewConnectionError: <urllib3.connection.HTTPConnection object at 0x7efc245802d0>: Failed to establish a new connection: [Errno 111] Connection refused
2019-12-12 03:51:27 [elasticsearch] DEBUG: > None
2019-12-12 03:51:27 [elasticsearch] WARNING: HEAD http://elasticsearch:9200/top [status:N/A request:0.006s]
Traceback (most recent call last):
  File "/usr/local/lib/python3.7/site-packages/urllib3/connection.py", line 157, in _new_conn
    (self._dns_host, self.port), self.timeout, **extra_kw
  File "/usr/local/lib/python3.7/site-packages/urllib3/util/connection.py", line 84, in create_connection
    raise err
  File "/usr/local/lib/python3.7/site-packages/urllib3/util/connection.py", line 74, in create_connection
    sock.connect(sa)
ConnectionRefusedError: [Errno 111] Connection refused

During handling of the above exception, another exception occurred:

Traceback (most recent call last):
  File "/usr/local/lib/python3.7/site-packages/elasticsearch/connection/http_urllib3.py", line 238, in perform_request
    method, url, body, retries=Retry(False), headers=request_headers, **kw
  File "/usr/local/lib/python3.7/site-packages/urllib3/connectionpool.py", line 720, in urlopen
    method, url, error=e, _pool=self, _stacktrace=sys.exc_info()[2]
  File "/usr/local/lib/python3.7/site-packages/urllib3/util/retry.py", line 376, in increment
    raise six.reraise(type(error), error, _stacktrace)
  File "/usr/local/lib/python3.7/site-packages/urllib3/packages/six.py", line 735, in reraise
    raise value
  File "/usr/local/lib/python3.7/site-packages/urllib3/connectionpool.py", line 672, in urlopen
    chunked=chunked,
  File "/usr/local/lib/python3.7/site-packages/urllib3/connectionpool.py", line 387, in _make_request
    conn.request(method, url, **httplib_request_kw)
  File "/usr/local/lib/python3.7/http/client.py", line 1252, in request
    self._send_request(method, url, body, headers, encode_chunked)
  File "/usr/local/lib/python3.7/http/client.py", line 1298, in _send_request
    self.endheaders(body, encode_chunked=encode_chunked)
  File "/usr/local/lib/python3.7/http/client.py", line 1247, in endheaders
    self._send_output(message_body, encode_chunked=encode_chunked)
  File "/usr/local/lib/python3.7/http/client.py", line 1026, in _send_output
    self.send(msg)
  File "/usr/local/lib/python3.7/http/client.py", line 966, in send
    self.connect()
  File "/usr/local/lib/python3.7/site-packages/urllib3/connection.py", line 184, in connect
    conn = self._new_conn()
  File "/usr/local/lib/python3.7/site-packages/urllib3/connection.py", line 169, in _new_conn
    self, "Failed to establish a new connection: %s" % e
urllib3.exceptions.NewConnectionError: <urllib3.connection.HTTPConnection object at 0x7efc24602450>: Failed to establish a new connection: [Errno 111] Connection refused
2019-12-12 03:51:27 [elasticsearch] DEBUG: > None
2019-12-12 03:51:27 [urllib3.connectionpool] DEBUG: Starting new HTTP connection (1): elasticsearch:9200
2019-12-12 03:51:27 [elasticsearch] WARNING: HEAD http://elasticsearch:9200/top [status:N/A request:0.004s]
Traceback (most recent call last):
  File "/usr/local/lib/python3.7/site-packages/urllib3/connection.py", line 157, in _new_conn
    (self._dns_host, self.port), self.timeout, **extra_kw
  File "/usr/local/lib/python3.7/site-packages/urllib3/util/connection.py", line 84, in create_connection
    raise err
  File "/usr/local/lib/python3.7/site-packages/urllib3/util/connection.py", line 74, in create_connection
    sock.connect(sa)
ConnectionRefusedError: [Errno 111] Connection refused

During handling of the above exception, another exception occurred:

Traceback (most recent call last):
  File "/usr/local/lib/python3.7/site-packages/elasticsearch/connection/http_urllib3.py", line 238, in perform_request
    method, url, body, retries=Retry(False), headers=request_headers, **kw
  File "/usr/local/lib/python3.7/site-packages/urllib3/connectionpool.py", line 720, in urlopen
    method, url, error=e, _pool=self, _stacktrace=sys.exc_info()[2]
  File "/usr/local/lib/python3.7/site-packages/urllib3/util/retry.py", line 376, in increment
    raise six.reraise(type(error), error, _stacktrace)
  File "/usr/local/lib/python3.7/site-packages/urllib3/packages/six.py", line 735, in reraise
    raise value
  File "/usr/local/lib/python3.7/site-packages/urllib3/connectionpool.py", line 672, in urlopen
    chunked=chunked,
  File "/usr/local/lib/python3.7/site-packages/urllib3/connectionpool.py", line 387, in _make_request
    conn.request(method, url, **httplib_request_kw)
  File "/usr/local/lib/python3.7/http/client.py", line 1252, in request
    self._send_request(method, url, body, headers, encode_chunked)
  File "/usr/local/lib/python3.7/http/client.py", line 1298, in _send_request
    self.endheaders(body, encode_chunked=encode_chunked)
  File "/usr/local/lib/python3.7/http/client.py", line 1247, in endheaders
    self._send_output(message_body, encode_chunked=encode_chunked)
  File "/usr/local/lib/python3.7/http/client.py", line 1026, in _send_output
    self.send(msg)
  File "/usr/local/lib/python3.7/http/client.py", line 966, in send
    self.connect()
  File "/usr/local/lib/python3.7/site-packages/urllib3/connection.py", line 184, in connect
    conn = self._new_conn()
  File "/usr/local/lib/python3.7/site-packages/urllib3/connection.py", line 169, in _new_conn
    self, "Failed to establish a new connection: %s" % e
urllib3.exceptions.NewConnectionError: <urllib3.connection.HTTPConnection object at 0x7efc25f0c0d0>: Failed to establish a new connection: [Errno 111] Connection refused
2019-12-12 03:51:27 [elasticsearch] DEBUG: > None
2019-12-12 03:51:27 [urllib3.connectionpool] DEBUG: Starting new HTTP connection (2): elasticsearch:9200
2019-12-12 03:51:27 [elasticsearch] WARNING: HEAD http://elasticsearch:9200/top [status:N/A request:0.001s]
Traceback (most recent call last):
  File "/usr/local/lib/python3.7/site-packages/urllib3/connection.py", line 157, in _new_conn
    (self._dns_host, self.port), self.timeout, **extra_kw
  File "/usr/local/lib/python3.7/site-packages/urllib3/util/connection.py", line 84, in create_connection
    raise err
  File "/usr/local/lib/python3.7/site-packages/urllib3/util/connection.py", line 74, in create_connection
    sock.connect(sa)
ConnectionRefusedError: [Errno 111] Connection refused

During handling of the above exception, another exception occurred:

Traceback (most recent call last):
  File "/usr/local/lib/python3.7/site-packages/elasticsearch/connection/http_urllib3.py", line 238, in perform_request
    method, url, body, retries=Retry(False), headers=request_headers, **kw
  File "/usr/local/lib/python3.7/site-packages/urllib3/connectionpool.py", line 720, in urlopen
    method, url, error=e, _pool=self, _stacktrace=sys.exc_info()[2]
  File "/usr/local/lib/python3.7/site-packages/urllib3/util/retry.py", line 376, in increment
    raise six.reraise(type(error), error, _stacktrace)
  File "/usr/local/lib/python3.7/site-packages/urllib3/packages/six.py", line 735, in reraise
    raise value
  File "/usr/local/lib/python3.7/site-packages/urllib3/connectionpool.py", line 672, in urlopen
    chunked=chunked,
  File "/usr/local/lib/python3.7/site-packages/urllib3/connectionpool.py", line 387, in _make_request
    conn.request(method, url, **httplib_request_kw)
  File "/usr/local/lib/python3.7/http/client.py", line 1252, in request
    self._send_request(method, url, body, headers, encode_chunked)
  File "/usr/local/lib/python3.7/http/client.py", line 1298, in _send_request
    self.endheaders(body, encode_chunked=encode_chunked)
  File "/usr/local/lib/python3.7/http/client.py", line 1247, in endheaders
    self._send_output(message_body, encode_chunked=encode_chunked)
  File "/usr/local/lib/python3.7/http/client.py", line 1026, in _send_output
    self.send(msg)
  File "/usr/local/lib/python3.7/http/client.py", line 966, in send
    self.connect()
  File "/usr/local/lib/python3.7/site-packages/urllib3/connection.py", line 184, in connect
    conn = self._new_conn()
  File "/usr/local/lib/python3.7/site-packages/urllib3/connection.py", line 169, in _new_conn
    self, "Failed to establish a new connection: %s" % e
urllib3.exceptions.NewConnectionError: <urllib3.connection.HTTPConnection object at 0x7efc24513650>: Failed to establish a new connection: [Errno 111] Connection refused
2019-12-12 03:51:27 [elasticsearch] DEBUG: > None
2019-12-12 03:51:27 [urllib3.connectionpool] DEBUG: Starting new HTTP connection (3): elasticsearch:9200
2019-12-12 03:51:27 [elasticsearch] WARNING: HEAD http://elasticsearch:9200/top [status:N/A request:0.006s]
Traceback (most recent call last):
  File "/usr/local/lib/python3.7/site-packages/urllib3/connection.py", line 157, in _new_conn
    (self._dns_host, self.port), self.timeout, **extra_kw
  File "/usr/local/lib/python3.7/site-packages/urllib3/util/connection.py", line 84, in create_connection
    raise err
  File "/usr/local/lib/python3.7/site-packages/urllib3/util/connection.py", line 74, in create_connection
    sock.connect(sa)
ConnectionRefusedError: [Errno 111] Connection refused

During handling of the above exception, another exception occurred:

Traceback (most recent call last):
  File "/usr/local/lib/python3.7/site-packages/elasticsearch/connection/http_urllib3.py", line 238, in perform_request
    method, url, body, retries=Retry(False), headers=request_headers, **kw
  File "/usr/local/lib/python3.7/site-packages/urllib3/connectionpool.py", line 720, in urlopen
    method, url, error=e, _pool=self, _stacktrace=sys.exc_info()[2]
  File "/usr/local/lib/python3.7/site-packages/urllib3/util/retry.py", line 376, in increment
    raise six.reraise(type(error), error, _stacktrace)
  File "/usr/local/lib/python3.7/site-packages/urllib3/packages/six.py", line 735, in reraise
    raise value
  File "/usr/local/lib/python3.7/site-packages/urllib3/connectionpool.py", line 672, in urlopen
    chunked=chunked,
  File "/usr/local/lib/python3.7/site-packages/urllib3/connectionpool.py", line 387, in _make_request
    conn.request(method, url, **httplib_request_kw)
  File "/usr/local/lib/python3.7/http/client.py", line 1252, in request
    self._send_request(method, url, body, headers, encode_chunked)
  File "/usr/local/lib/python3.7/http/client.py", line 1298, in _send_request
    self.endheaders(body, encode_chunked=encode_chunked)
  File "/usr/local/lib/python3.7/http/client.py", line 1247, in endheaders
    self._send_output(message_body, encode_chunked=encode_chunked)
  File "/usr/local/lib/python3.7/http/client.py", line 1026, in _send_output
    self.send(msg)
  File "/usr/local/lib/python3.7/http/client.py", line 966, in send
    self.connect()
  File "/usr/local/lib/python3.7/site-packages/urllib3/connection.py", line 184, in connect
    conn = self._new_conn()
  File "/usr/local/lib/python3.7/site-packages/urllib3/connection.py", line 169, in _new_conn
    self, "Failed to establish a new connection: %s" % e
urllib3.exceptions.NewConnectionError: <urllib3.connection.HTTPConnection object at 0x7efc24513910>: Failed to establish a new connection: [Errno 111] Connection refused
2019-12-12 03:51:27 [elasticsearch] DEBUG: > None
2019-12-12 03:51:27 [urllib3.connectionpool] DEBUG: Starting new HTTP connection (4): elasticsearch:9200
2019-12-12 03:51:27 [urllib3.connectionpool] DEBUG: Starting new HTTP connection (1): elasticsearch:9200
2019-12-12 03:51:27 [urllib3.connectionpool] DEBUG: Starting new HTTP connection (1): elasticsearch:9200
2019-12-12 03:51:27 [urllib3.connectionpool] DEBUG: Starting new HTTP connection (1): elasticsearch:9200
2019-12-12 03:51:27 [urllib3.connectionpool] DEBUG: Starting new HTTP connection (1): elasticsearch:9200
2019-12-12 03:51:27 [elasticsearch] WARNING: HEAD http://elasticsearch:9200/top [status:N/A request:0.007s]
Traceback (most recent call last):
  File "/usr/local/lib/python3.7/site-packages/urllib3/connection.py", line 157, in _new_conn
    (self._dns_host, self.port), self.timeout, **extra_kw
  File "/usr/local/lib/python3.7/site-packages/urllib3/util/connection.py", line 84, in create_connection
    raise err
  File "/usr/local/lib/python3.7/site-packages/urllib3/util/connection.py", line 74, in create_connection
    sock.connect(sa)
ConnectionRefusedError: [Errno 111] Connection refused

During handling of the above exception, another exception occurred:

Traceback (most recent call last):
  File "/usr/local/lib/python3.7/site-packages/elasticsearch/connection/http_urllib3.py", line 238, in perform_request
    method, url, body, retries=Retry(False), headers=request_headers, **kw
  File "/usr/local/lib/python3.7/site-packages/urllib3/connectionpool.py", line 720, in urlopen
    method, url, error=e, _pool=self, _stacktrace=sys.exc_info()[2]
  File "/usr/local/lib/python3.7/site-packages/urllib3/util/retry.py", line 376, in increment
    raise six.reraise(type(error), error, _stacktrace)
  File "/usr/local/lib/python3.7/site-packages/urllib3/packages/six.py", line 735, in reraise
    raise value
  File "/usr/local/lib/python3.7/site-packages/urllib3/connectionpool.py", line 672, in urlopen
    chunked=chunked,
  File "/usr/local/lib/python3.7/site-packages/urllib3/connectionpool.py", line 387, in _make_request
    conn.request(method, url, **httplib_request_kw)
  File "/usr/local/lib/python3.7/http/client.py", line 1252, in request
    self._send_request(method, url, body, headers, encode_chunked)
  File "/usr/local/lib/python3.7/http/client.py", line 1298, in _send_request
    self.endheaders(body, encode_chunked=encode_chunked)
  File "/usr/local/lib/python3.7/http/client.py", line 1247, in endheaders
    self._send_output(message_body, encode_chunked=encode_chunked)
  File "/usr/local/lib/python3.7/http/client.py", line 1026, in _send_output
    self.send(msg)
  File "/usr/local/lib/python3.7/http/client.py", line 966, in send
    self.connect()
  File "/usr/local/lib/python3.7/site-packages/urllib3/connection.py", line 184, in connect
    conn = self._new_conn()
  File "/usr/local/lib/python3.7/site-packages/urllib3/connection.py", line 169, in _new_conn
    self, "Failed to establish a new connection: %s" % e
urllib3.exceptions.NewConnectionError: <urllib3.connection.HTTPConnection object at 0x7efc24526610>: Failed to establish a new connection: [Errno 111] Connection refused
2019-12-12 03:51:27 [elasticsearch] DEBUG: > None
2019-12-12 03:51:27 [urllib3.connectionpool] DEBUG: Starting new HTTP connection (2): elasticsearch:9200
2019-12-12 03:51:27 [elasticsearch] WARNING: HEAD http://elasticsearch:9200/top [status:N/A request:0.009s]
Traceback (most recent call last):
  File "/usr/local/lib/python3.7/site-packages/urllib3/connection.py", line 157, in _new_conn
    (self._dns_host, self.port), self.timeout, **extra_kw
  File "/usr/local/lib/python3.7/site-packages/urllib3/util/connection.py", line 84, in create_connection
    raise err
  File "/usr/local/lib/python3.7/site-packages/urllib3/util/connection.py", line 74, in create_connection
    sock.connect(sa)
ConnectionRefusedError: [Errno 111] Connection refused

During handling of the above exception, another exception occurred:

Traceback (most recent call last):
  File "/usr/local/lib/python3.7/site-packages/elasticsearch/connection/http_urllib3.py", line 238, in perform_request
    method, url, body, retries=Retry(False), headers=request_headers, **kw
  File "/usr/local/lib/python3.7/site-packages/urllib3/connectionpool.py", line 720, in urlopen
    method, url, error=e, _pool=self, _stacktrace=sys.exc_info()[2]
  File "/usr/local/lib/python3.7/site-packages/urllib3/util/retry.py", line 376, in increment
    raise six.reraise(type(error), error, _stacktrace)
  File "/usr/local/lib/python3.7/site-packages/urllib3/packages/six.py", line 735, in reraise
    raise value
  File "/usr/local/lib/python3.7/site-packages/urllib3/connectionpool.py", line 672, in urlopen
    chunked=chunked,
  File "/usr/local/lib/python3.7/site-packages/urllib3/connectionpool.py", line 387, in _make_request
    conn.request(method, url, **httplib_request_kw)
  File "/usr/local/lib/python3.7/http/client.py", line 1252, in request
    self._send_request(method, url, body, headers, encode_chunked)
  File "/usr/local/lib/python3.7/http/client.py", line 1298, in _send_request
    self.endheaders(body, encode_chunked=encode_chunked)
  File "/usr/local/lib/python3.7/http/client.py", line 1247, in endheaders
    self._send_output(message_body, encode_chunked=encode_chunked)
  File "/usr/local/lib/python3.7/http/client.py", line 1026, in _send_output
    self.send(msg)
  File "/usr/local/lib/python3.7/http/client.py", line 966, in send
    self.connect()
  File "/usr/local/lib/python3.7/site-packages/urllib3/connection.py", line 184, in connect
    conn = self._new_conn()
  File "/usr/local/lib/python3.7/site-packages/urllib3/connection.py", line 169, in _new_conn
    self, "Failed to establish a new connection: %s" % e
urllib3.exceptions.NewConnectionError: <urllib3.connection.HTTPConnection object at 0x7efc24523890>: Failed to establish a new connection: [Errno 111] Connection refused
2019-12-12 03:51:27 [elasticsearch] DEBUG: > None
2019-12-12 03:51:27 [urllib3.connectionpool] DEBUG: Starting new HTTP connection (2): elasticsearch:9200
2019-12-12 03:51:27 [elasticsearch] WARNING: HEAD http://elasticsearch:9200/top [status:N/A request:0.010s]
Traceback (most recent call last):
  File "/usr/local/lib/python3.7/site-packages/urllib3/connection.py", line 157, in _new_conn
    (self._dns_host, self.port), self.timeout, **extra_kw
  File "/usr/local/lib/python3.7/site-packages/urllib3/util/connection.py", line 84, in create_connection
    raise err
  File "/usr/local/lib/python3.7/site-packages/urllib3/util/connection.py", line 74, in create_connection
    sock.connect(sa)
ConnectionRefusedError: [Errno 111] Connection refused

During handling of the above exception, another exception occurred:

Traceback (most recent call last):
  File "/usr/local/lib/python3.7/site-packages/elasticsearch/connection/http_urllib3.py", line 238, in perform_request
    method, url, body, retries=Retry(False), headers=request_headers, **kw
  File "/usr/local/lib/python3.7/site-packages/urllib3/connectionpool.py", line 720, in urlopen
    method, url, error=e, _pool=self, _stacktrace=sys.exc_info()[2]
  File "/usr/local/lib/python3.7/site-packages/urllib3/util/retry.py", line 376, in increment
    raise six.reraise(type(error), error, _stacktrace)
  File "/usr/local/lib/python3.7/site-packages/urllib3/packages/six.py", line 735, in reraise
    raise value
  File "/usr/local/lib/python3.7/site-packages/urllib3/connectionpool.py", line 672, in urlopen
    chunked=chunked,
  File "/usr/local/lib/python3.7/site-packages/urllib3/connectionpool.py", line 387, in _make_request
    conn.request(method, url, **httplib_request_kw)
  File "/usr/local/lib/python3.7/http/client.py", line 1252, in request
    self._send_request(method, url, body, headers, encode_chunked)
  File "/usr/local/lib/python3.7/http/client.py", line 1298, in _send_request
    self.endheaders(body, encode_chunked=encode_chunked)
  File "/usr/local/lib/python3.7/http/client.py", line 1247, in endheaders
    self._send_output(message_body, encode_chunked=encode_chunked)
  File "/usr/local/lib/python3.7/http/client.py", line 1026, in _send_output
    self.send(msg)
  File "/usr/local/lib/python3.7/http/client.py", line 966, in send
    self.connect()
  File "/usr/local/lib/python3.7/site-packages/urllib3/connection.py", line 184, in connect
    conn = self._new_conn()
  File "/usr/local/lib/python3.7/site-packages/urllib3/connection.py", line 169, in _new_conn
    self, "Failed to establish a new connection: %s" % e
urllib3.exceptions.NewConnectionError: <urllib3.connection.HTTPConnection object at 0x7efc2451fb10>: Failed to establish a new connection: [Errno 111] Connection refused
2019-12-12 03:51:27 [elasticsearch] DEBUG: > None
2019-12-12 03:51:27 [urllib3.connectionpool] DEBUG: Starting new HTTP connection (2): elasticsearch:9200
2019-12-12 03:51:27 [elasticsearch] WARNING: HEAD http://elasticsearch:9200/top [status:N/A request:0.012s]
Traceback (most recent call last):
  File "/usr/local/lib/python3.7/site-packages/urllib3/connection.py", line 157, in _new_conn
    (self._dns_host, self.port), self.timeout, **extra_kw
  File "/usr/local/lib/python3.7/site-packages/urllib3/util/connection.py", line 84, in create_connection
    raise err
  File "/usr/local/lib/python3.7/site-packages/urllib3/util/connection.py", line 74, in create_connection
    sock.connect(sa)
ConnectionRefusedError: [Errno 111] Connection refused

During handling of the above exception, another exception occurred:

Traceback (most recent call last):
  File "/usr/local/lib/python3.7/site-packages/elasticsearch/connection/http_urllib3.py", line 238, in perform_request
    method, url, body, retries=Retry(False), headers=request_headers, **kw
  File "/usr/local/lib/python3.7/site-packages/urllib3/connectionpool.py", line 720, in urlopen
    method, url, error=e, _pool=self, _stacktrace=sys.exc_info()[2]
  File "/usr/local/lib/python3.7/site-packages/urllib3/util/retry.py", line 376, in increment
    raise six.reraise(type(error), error, _stacktrace)
  File "/usr/local/lib/python3.7/site-packages/urllib3/packages/six.py", line 735, in reraise
    raise value
  File "/usr/local/lib/python3.7/site-packages/urllib3/connectionpool.py", line 672, in urlopen
    chunked=chunked,
  File "/usr/local/lib/python3.7/site-packages/urllib3/connectionpool.py", line 387, in _make_request
    conn.request(method, url, **httplib_request_kw)
  File "/usr/local/lib/python3.7/http/client.py", line 1252, in request
    self._send_request(method, url, body, headers, encode_chunked)
  File "/usr/local/lib/python3.7/http/client.py", line 1298, in _send_request
    self.endheaders(body, encode_chunked=encode_chunked)
  File "/usr/local/lib/python3.7/http/client.py", line 1247, in endheaders
    self._send_output(message_body, encode_chunked=encode_chunked)
  File "/usr/local/lib/python3.7/http/client.py", line 1026, in _send_output
    self.send(msg)
  File "/usr/local/lib/python3.7/http/client.py", line 966, in send
    self.connect()
  File "/usr/local/lib/python3.7/site-packages/urllib3/connection.py", line 184, in connect
    conn = self._new_conn()
  File "/usr/local/lib/python3.7/site-packages/urllib3/connection.py", line 169, in _new_conn
    self, "Failed to establish a new connection: %s" % e
urllib3.exceptions.NewConnectionError: <urllib3.connection.HTTPConnection object at 0x7efc245135d0>: Failed to establish a new connection: [Errno 111] Connection refused
2019-12-12 03:51:27 [elasticsearch] DEBUG: > None
2019-12-12 03:51:27 [urllib3.connectionpool] DEBUG: Starting new HTTP connection (2): elasticsearch:9200
2019-12-12 03:51:27 [elasticsearch] WARNING: HEAD http://elasticsearch:9200/top [status:N/A request:0.014s]
Traceback (most recent call last):
  File "/usr/local/lib/python3.7/site-packages/urllib3/connection.py", line 157, in _new_conn
    (self._dns_host, self.port), self.timeout, **extra_kw
  File "/usr/local/lib/python3.7/site-packages/urllib3/util/connection.py", line 84, in create_connection
    raise err
  File "/usr/local/lib/python3.7/site-packages/urllib3/util/connection.py", line 74, in create_connection
    sock.connect(sa)
ConnectionRefusedError: [Errno 111] Connection refused

During handling of the above exception, another exception occurred:

Traceback (most recent call last):
  File "/usr/local/lib/python3.7/site-packages/elasticsearch/connection/http_urllib3.py", line 238, in perform_request
    method, url, body, retries=Retry(False), headers=request_headers, **kw
  File "/usr/local/lib/python3.7/site-packages/urllib3/connectionpool.py", line 720, in urlopen
    method, url, error=e, _pool=self, _stacktrace=sys.exc_info()[2]
  File "/usr/local/lib/python3.7/site-packages/urllib3/util/retry.py", line 376, in increment
    raise six.reraise(type(error), error, _stacktrace)
  File "/usr/local/lib/python3.7/site-packages/urllib3/packages/six.py", line 735, in reraise
    raise value
  File "/usr/local/lib/python3.7/site-packages/urllib3/connectionpool.py", line 672, in urlopen
    chunked=chunked,
  File "/usr/local/lib/python3.7/site-packages/urllib3/connectionpool.py", line 387, in _make_request
    conn.request(method, url, **httplib_request_kw)
  File "/usr/local/lib/python3.7/http/client.py", line 1252, in request
    self._send_request(method, url, body, headers, encode_chunked)
  File "/usr/local/lib/python3.7/http/client.py", line 1298, in _send_request
    self.endheaders(body, encode_chunked=encode_chunked)
  File "/usr/local/lib/python3.7/http/client.py", line 1247, in endheaders
    self._send_output(message_body, encode_chunked=encode_chunked)
  File "/usr/local/lib/python3.7/http/client.py", line 1026, in _send_output
    self.send(msg)
  File "/usr/local/lib/python3.7/http/client.py", line 966, in send
    self.connect()
  File "/usr/local/lib/python3.7/site-packages/urllib3/connection.py", line 184, in connect
    conn = self._new_conn()
  File "/usr/local/lib/python3.7/site-packages/urllib3/connection.py", line 169, in _new_conn
    self, "Failed to establish a new connection: %s" % e
urllib3.exceptions.NewConnectionError: <urllib3.connection.HTTPConnection object at 0x7efc245806d0>: Failed to establish a new connection: [Errno 111] Connection refused
2019-12-12 03:51:27 [elasticsearch] DEBUG: > None
2019-12-12 03:51:27 [elasticsearch] WARNING: HEAD http://elasticsearch:9200/top [status:N/A request:0.006s]
Traceback (most recent call last):
  File "/usr/local/lib/python3.7/site-packages/urllib3/connection.py", line 157, in _new_conn
    (self._dns_host, self.port), self.timeout, **extra_kw
  File "/usr/local/lib/python3.7/site-packages/urllib3/util/connection.py", line 84, in create_connection
    raise err
  File "/usr/local/lib/python3.7/site-packages/urllib3/util/connection.py", line 74, in create_connection
    sock.connect(sa)
ConnectionRefusedError: [Errno 111] Connection refused

During handling of the above exception, another exception occurred:

Traceback (most recent call last):
  File "/usr/local/lib/python3.7/site-packages/elasticsearch/connection/http_urllib3.py", line 238, in perform_request
    method, url, body, retries=Retry(False), headers=request_headers, **kw
  File "/usr/local/lib/python3.7/site-packages/urllib3/connectionpool.py", line 720, in urlopen
    method, url, error=e, _pool=self, _stacktrace=sys.exc_info()[2]
  File "/usr/local/lib/python3.7/site-packages/urllib3/util/retry.py", line 376, in increment
    raise six.reraise(type(error), error, _stacktrace)
  File "/usr/local/lib/python3.7/site-packages/urllib3/packages/six.py", line 735, in reraise
    raise value
  File "/usr/local/lib/python3.7/site-packages/urllib3/connectionpool.py", line 672, in urlopen
    chunked=chunked,
  File "/usr/local/lib/python3.7/site-packages/urllib3/connectionpool.py", line 387, in _make_request
    conn.request(method, url, **httplib_request_kw)
  File "/usr/local/lib/python3.7/http/client.py", line 1252, in request
    self._send_request(method, url, body, headers, encode_chunked)
  File "/usr/local/lib/python3.7/http/client.py", line 1298, in _send_request
    self.endheaders(body, encode_chunked=encode_chunked)
  File "/usr/local/lib/python3.7/http/client.py", line 1247, in endheaders
    self._send_output(message_body, encode_chunked=encode_chunked)
  File "/usr/local/lib/python3.7/http/client.py", line 1026, in _send_output
    self.send(msg)
  File "/usr/local/lib/python3.7/http/client.py", line 966, in send
    self.connect()
  File "/usr/local/lib/python3.7/site-packages/urllib3/connection.py", line 184, in connect
    conn = self._new_conn()
  File "/usr/local/lib/python3.7/site-packages/urllib3/connection.py", line 169, in _new_conn
    self, "Failed to establish a new connection: %s" % e
urllib3.exceptions.NewConnectionError: <urllib3.connection.HTTPConnection object at 0x7efc24526cd0>: Failed to establish a new connection: [Errno 111] Connection refused
2019-12-12 03:51:27 [elasticsearch] DEBUG: > None
2019-12-12 03:51:27 [urllib3.connectionpool] DEBUG: Starting new HTTP connection (3): elasticsearch:9200
2019-12-12 03:51:27 [elasticsearch] WARNING: HEAD http://elasticsearch:9200/top [status:N/A request:0.008s]
Traceback (most recent call last):
  File "/usr/local/lib/python3.7/site-packages/urllib3/connection.py", line 157, in _new_conn
    (self._dns_host, self.port), self.timeout, **extra_kw
  File "/usr/local/lib/python3.7/site-packages/urllib3/util/connection.py", line 84, in create_connection
    raise err
  File "/usr/local/lib/python3.7/site-packages/urllib3/util/connection.py", line 74, in create_connection
    sock.connect(sa)
ConnectionRefusedError: [Errno 111] Connection refused

During handling of the above exception, another exception occurred:

Traceback (most recent call last):
  File "/usr/local/lib/python3.7/site-packages/elasticsearch/connection/http_urllib3.py", line 238, in perform_request
    method, url, body, retries=Retry(False), headers=request_headers, **kw
  File "/usr/local/lib/python3.7/site-packages/urllib3/connectionpool.py", line 720, in urlopen
    method, url, error=e, _pool=self, _stacktrace=sys.exc_info()[2]
  File "/usr/local/lib/python3.7/site-packages/urllib3/util/retry.py", line 376, in increment
    raise six.reraise(type(error), error, _stacktrace)
  File "/usr/local/lib/python3.7/site-packages/urllib3/packages/six.py", line 735, in reraise
    raise value
  File "/usr/local/lib/python3.7/site-packages/urllib3/connectionpool.py", line 672, in urlopen
    chunked=chunked,
  File "/usr/local/lib/python3.7/site-packages/urllib3/connectionpool.py", line 387, in _make_request
    conn.request(method, url, **httplib_request_kw)
  File "/usr/local/lib/python3.7/http/client.py", line 1252, in request
    self._send_request(method, url, body, headers, encode_chunked)
  File "/usr/local/lib/python3.7/http/client.py", line 1298, in _send_request
    self.endheaders(body, encode_chunked=encode_chunked)
  File "/usr/local/lib/python3.7/http/client.py", line 1247, in endheaders
    self._send_output(message_body, encode_chunked=encode_chunked)
  File "/usr/local/lib/python3.7/http/client.py", line 1026, in _send_output
    self.send(msg)
  File "/usr/local/lib/python3.7/http/client.py", line 966, in send
    self.connect()
  File "/usr/local/lib/python3.7/site-packages/urllib3/connection.py", line 184, in connect
    conn = self._new_conn()
  File "/usr/local/lib/python3.7/site-packages/urllib3/connection.py", line 169, in _new_conn
    self, "Failed to establish a new connection: %s" % e
urllib3.exceptions.NewConnectionError: <urllib3.connection.HTTPConnection object at 0x7efc24526a50>: Failed to establish a new connection: [Errno 111] Connection refused
2019-12-12 03:51:27 [elasticsearch] DEBUG: > None
2019-12-12 03:51:27 [urllib3.connectionpool] DEBUG: Starting new HTTP connection (3): elasticsearch:9200
2019-12-12 03:51:27 [elasticsearch] WARNING: HEAD http://elasticsearch:9200/top [status:N/A request:0.007s]
Traceback (most recent call last):
  File "/usr/local/lib/python3.7/site-packages/urllib3/connection.py", line 157, in _new_conn
    (self._dns_host, self.port), self.timeout, **extra_kw
  File "/usr/local/lib/python3.7/site-packages/urllib3/util/connection.py", line 84, in create_connection
    raise err
  File "/usr/local/lib/python3.7/site-packages/urllib3/util/connection.py", line 74, in create_connection
    sock.connect(sa)
ConnectionRefusedError: [Errno 111] Connection refused

During handling of the above exception, another exception occurred:

Traceback (most recent call last):
  File "/usr/local/lib/python3.7/site-packages/elasticsearch/connection/http_urllib3.py", line 238, in perform_request
    method, url, body, retries=Retry(False), headers=request_headers, **kw
  File "/usr/local/lib/python3.7/site-packages/urllib3/connectionpool.py", line 720, in urlopen
    method, url, error=e, _pool=self, _stacktrace=sys.exc_info()[2]
  File "/usr/local/lib/python3.7/site-packages/urllib3/util/retry.py", line 376, in increment
    raise six.reraise(type(error), error, _stacktrace)
  File "/usr/local/lib/python3.7/site-packages/urllib3/packages/six.py", line 735, in reraise
    raise value
  File "/usr/local/lib/python3.7/site-packages/urllib3/connectionpool.py", line 672, in urlopen
    chunked=chunked,
  File "/usr/local/lib/python3.7/site-packages/urllib3/connectionpool.py", line 387, in _make_request
    conn.request(method, url, **httplib_request_kw)
  File "/usr/local/lib/python3.7/http/client.py", line 1252, in request
    self._send_request(method, url, body, headers, encode_chunked)
  File "/usr/local/lib/python3.7/http/client.py", line 1298, in _send_request
    self.endheaders(body, encode_chunked=encode_chunked)
  File "/usr/local/lib/python3.7/http/client.py", line 1247, in endheaders
    self._send_output(message_body, encode_chunked=encode_chunked)
  File "/usr/local/lib/python3.7/http/client.py", line 1026, in _send_output
    self.send(msg)
  File "/usr/local/lib/python3.7/http/client.py", line 966, in send
    self.connect()
  File "/usr/local/lib/python3.7/site-packages/urllib3/connection.py", line 184, in connect
    conn = self._new_conn()
  File "/usr/local/lib/python3.7/site-packages/urllib3/connection.py", line 169, in _new_conn
    self, "Failed to establish a new connection: %s" % e
urllib3.exceptions.NewConnectionError: <urllib3.connection.HTTPConnection object at 0x7efc2452d050>: Failed to establish a new connection: [Errno 111] Connection refused
2019-12-12 03:51:27 [elasticsearch] DEBUG: > None
2019-12-12 03:51:27 [urllib3.connectionpool] DEBUG: Starting new HTTP connection (3): elasticsearch:9200
2019-12-12 03:51:27 [elasticsearch] WARNING: HEAD http://elasticsearch:9200/top [status:N/A request:0.011s]
Traceback (most recent call last):
  File "/usr/local/lib/python3.7/site-packages/urllib3/connection.py", line 157, in _new_conn
    (self._dns_host, self.port), self.timeout, **extra_kw
  File "/usr/local/lib/python3.7/site-packages/urllib3/util/connection.py", line 84, in create_connection
    raise err
  File "/usr/local/lib/python3.7/site-packages/urllib3/util/connection.py", line 74, in create_connection
    sock.connect(sa)
ConnectionRefusedError: [Errno 111] Connection refused

During handling of the above exception, another exception occurred:

Traceback (most recent call last):
  File "/usr/local/lib/python3.7/site-packages/elasticsearch/connection/http_urllib3.py", line 238, in perform_request
    method, url, body, retries=Retry(False), headers=request_headers, **kw
  File "/usr/local/lib/python3.7/site-packages/urllib3/connectionpool.py", line 720, in urlopen
    method, url, error=e, _pool=self, _stacktrace=sys.exc_info()[2]
  File "/usr/local/lib/python3.7/site-packages/urllib3/util/retry.py", line 376, in increment
    raise six.reraise(type(error), error, _stacktrace)
  File "/usr/local/lib/python3.7/site-packages/urllib3/packages/six.py", line 735, in reraise
    raise value
  File "/usr/local/lib/python3.7/site-packages/urllib3/connectionpool.py", line 672, in urlopen
    chunked=chunked,
  File "/usr/local/lib/python3.7/site-packages/urllib3/connectionpool.py", line 387, in _make_request
    conn.request(method, url, **httplib_request_kw)
  File "/usr/local/lib/python3.7/http/client.py", line 1252, in request
    self._send_request(method, url, body, headers, encode_chunked)
  File "/usr/local/lib/python3.7/http/client.py", line 1298, in _send_request
    self.endheaders(body, encode_chunked=encode_chunked)
  File "/usr/local/lib/python3.7/http/client.py", line 1247, in endheaders
    self._send_output(message_body, encode_chunked=encode_chunked)
  File "/usr/local/lib/python3.7/http/client.py", line 1026, in _send_output
    self.send(msg)
  File "/usr/local/lib/python3.7/http/client.py", line 966, in send
    self.connect()
  File "/usr/local/lib/python3.7/site-packages/urllib3/connection.py", line 184, in connect
    conn = self._new_conn()
  File "/usr/local/lib/python3.7/site-packages/urllib3/connection.py", line 169, in _new_conn
    self, "Failed to establish a new connection: %s" % e
urllib3.exceptions.NewConnectionError: <urllib3.connection.HTTPConnection object at 0x7efc24526790>: Failed to establish a new connection: [Errno 111] Connection refused
2019-12-12 03:51:27 [elasticsearch] DEBUG: > None
2019-12-12 03:51:27 [urllib3.connectionpool] DEBUG: Starting new HTTP connection (3): elasticsearch:9200
2019-12-12 03:51:27 [elasticsearch] WARNING: HEAD http://elasticsearch:9200/top [status:N/A request:0.006s]
Traceback (most recent call last):
  File "/usr/local/lib/python3.7/site-packages/urllib3/connection.py", line 157, in _new_conn
    (self._dns_host, self.port), self.timeout, **extra_kw
  File "/usr/local/lib/python3.7/site-packages/urllib3/util/connection.py", line 84, in create_connection
    raise err
  File "/usr/local/lib/python3.7/site-packages/urllib3/util/connection.py", line 74, in create_connection
    sock.connect(sa)
ConnectionRefusedError: [Errno 111] Connection refused

During handling of the above exception, another exception occurred:

Traceback (most recent call last):
  File "/usr/local/lib/python3.7/site-packages/elasticsearch/connection/http_urllib3.py", line 238, in perform_request
    method, url, body, retries=Retry(False), headers=request_headers, **kw
  File "/usr/local/lib/python3.7/site-packages/urllib3/connectionpool.py", line 720, in urlopen
    method, url, error=e, _pool=self, _stacktrace=sys.exc_info()[2]
  File "/usr/local/lib/python3.7/site-packages/urllib3/util/retry.py", line 376, in increment
    raise six.reraise(type(error), error, _stacktrace)
  File "/usr/local/lib/python3.7/site-packages/urllib3/packages/six.py", line 735, in reraise
    raise value
  File "/usr/local/lib/python3.7/site-packages/urllib3/connectionpool.py", line 672, in urlopen
    chunked=chunked,
  File "/usr/local/lib/python3.7/site-packages/urllib3/connectionpool.py", line 387, in _make_request
    conn.request(method, url, **httplib_request_kw)
  File "/usr/local/lib/python3.7/http/client.py", line 1252, in request
    self._send_request(method, url, body, headers, encode_chunked)
  File "/usr/local/lib/python3.7/http/client.py", line 1298, in _send_request
    self.endheaders(body, encode_chunked=encode_chunked)
  File "/usr/local/lib/python3.7/http/client.py", line 1247, in endheaders
    self._send_output(message_body, encode_chunked=encode_chunked)
  File "/usr/local/lib/python3.7/http/client.py", line 1026, in _send_output
    self.send(msg)
  File "/usr/local/lib/python3.7/http/client.py", line 966, in send
    self.connect()
  File "/usr/local/lib/python3.7/site-packages/urllib3/connection.py", line 184, in connect
    conn = self._new_conn()
  File "/usr/local/lib/python3.7/site-packages/urllib3/connection.py", line 169, in _new_conn
    self, "Failed to establish a new connection: %s" % e
urllib3.exceptions.NewConnectionError: <urllib3.connection.HTTPConnection object at 0x7efc245237d0>: Failed to establish a new connection: [Errno 111] Connection refused
2019-12-12 03:51:27 [elasticsearch] DEBUG: > None
2019-12-12 03:51:27 [urllib3.connectionpool] DEBUG: Starting new HTTP connection (4): elasticsearch:9200
2019-12-12 03:51:27 [elasticsearch] WARNING: HEAD http://elasticsearch:9200/top [status:N/A request:0.006s]
Traceback (most recent call last):
  File "/usr/local/lib/python3.7/site-packages/urllib3/connection.py", line 157, in _new_conn
    (self._dns_host, self.port), self.timeout, **extra_kw
  File "/usr/local/lib/python3.7/site-packages/urllib3/util/connection.py", line 84, in create_connection
    raise err
  File "/usr/local/lib/python3.7/site-packages/urllib3/util/connection.py", line 74, in create_connection
    sock.connect(sa)
ConnectionRefusedError: [Errno 111] Connection refused

During handling of the above exception, another exception occurred:

Traceback (most recent call last):
  File "/usr/local/lib/python3.7/site-packages/elasticsearch/connection/http_urllib3.py", line 238, in perform_request
    method, url, body, retries=Retry(False), headers=request_headers, **kw
  File "/usr/local/lib/python3.7/site-packages/urllib3/connectionpool.py", line 720, in urlopen
    method, url, error=e, _pool=self, _stacktrace=sys.exc_info()[2]
  File "/usr/local/lib/python3.7/site-packages/urllib3/util/retry.py", line 376, in increment
    raise six.reraise(type(error), error, _stacktrace)
  File "/usr/local/lib/python3.7/site-packages/urllib3/packages/six.py", line 735, in reraise
    raise value
  File "/usr/local/lib/python3.7/site-packages/urllib3/connectionpool.py", line 672, in urlopen
    chunked=chunked,
  File "/usr/local/lib/python3.7/site-packages/urllib3/connectionpool.py", line 387, in _make_request
    conn.request(method, url, **httplib_request_kw)
  File "/usr/local/lib/python3.7/http/client.py", line 1252, in request
    self._send_request(method, url, body, headers, encode_chunked)
  File "/usr/local/lib/python3.7/http/client.py", line 1298, in _send_request
    self.endheaders(body, encode_chunked=encode_chunked)
  File "/usr/local/lib/python3.7/http/client.py", line 1247, in endheaders
    self._send_output(message_body, encode_chunked=encode_chunked)
  File "/usr/local/lib/python3.7/http/client.py", line 1026, in _send_output
    self.send(msg)
  File "/usr/local/lib/python3.7/http/client.py", line 966, in send
    self.connect()
  File "/usr/local/lib/python3.7/site-packages/urllib3/connection.py", line 184, in connect
    conn = self._new_conn()
  File "/usr/local/lib/python3.7/site-packages/urllib3/connection.py", line 169, in _new_conn
    self, "Failed to establish a new connection: %s" % e
urllib3.exceptions.NewConnectionError: <urllib3.connection.HTTPConnection object at 0x7efc2451fad0>: Failed to establish a new connection: [Errno 111] Connection refused
2019-12-12 03:51:27 [elasticsearch] DEBUG: > None
2019-12-12 03:51:27 [urllib3.connectionpool] DEBUG: Starting new HTTP connection (4): elasticsearch:9200
2019-12-12 03:51:27 [elasticsearch] WARNING: HEAD http://elasticsearch:9200/top [status:N/A request:0.008s]
Traceback (most recent call last):
  File "/usr/local/lib/python3.7/site-packages/urllib3/connection.py", line 157, in _new_conn
    (self._dns_host, self.port), self.timeout, **extra_kw
  File "/usr/local/lib/python3.7/site-packages/urllib3/util/connection.py", line 84, in create_connection
    raise err
  File "/usr/local/lib/python3.7/site-packages/urllib3/util/connection.py", line 74, in create_connection
    sock.connect(sa)
ConnectionRefusedError: [Errno 111] Connection refused

During handling of the above exception, another exception occurred:

Traceback (most recent call last):
  File "/usr/local/lib/python3.7/site-packages/elasticsearch/connection/http_urllib3.py", line 238, in perform_request
    method, url, body, retries=Retry(False), headers=request_headers, **kw
  File "/usr/local/lib/python3.7/site-packages/urllib3/connectionpool.py", line 720, in urlopen
    method, url, error=e, _pool=self, _stacktrace=sys.exc_info()[2]
  File "/usr/local/lib/python3.7/site-packages/urllib3/util/retry.py", line 376, in increment
    raise six.reraise(type(error), error, _stacktrace)
  File "/usr/local/lib/python3.7/site-packages/urllib3/packages/six.py", line 735, in reraise
    raise value
  File "/usr/local/lib/python3.7/site-packages/urllib3/connectionpool.py", line 672, in urlopen
    chunked=chunked,
  File "/usr/local/lib/python3.7/site-packages/urllib3/connectionpool.py", line 387, in _make_request
    conn.request(method, url, **httplib_request_kw)
  File "/usr/local/lib/python3.7/http/client.py", line 1252, in request
    self._send_request(method, url, body, headers, encode_chunked)
  File "/usr/local/lib/python3.7/http/client.py", line 1298, in _send_request
    self.endheaders(body, encode_chunked=encode_chunked)
  File "/usr/local/lib/python3.7/http/client.py", line 1247, in endheaders
    self._send_output(message_body, encode_chunked=encode_chunked)
  File "/usr/local/lib/python3.7/http/client.py", line 1026, in _send_output
    self.send(msg)
  File "/usr/local/lib/python3.7/http/client.py", line 966, in send
    self.connect()
  File "/usr/local/lib/python3.7/site-packages/urllib3/connection.py", line 184, in connect
    conn = self._new_conn()
  File "/usr/local/lib/python3.7/site-packages/urllib3/connection.py", line 169, in _new_conn
    self, "Failed to establish a new connection: %s" % e
urllib3.exceptions.NewConnectionError: <urllib3.connection.HTTPConnection object at 0x7efc24526590>: Failed to establish a new connection: [Errno 111] Connection refused
2019-12-12 03:51:27 [elasticsearch] DEBUG: > None
2019-12-12 03:51:27 [urllib3.connectionpool] DEBUG: Starting new HTTP connection (4): elasticsearch:9200
2019-12-12 03:51:27 [elasticsearch] WARNING: HEAD http://elasticsearch:9200/top [status:N/A request:0.007s]
Traceback (most recent call last):
  File "/usr/local/lib/python3.7/site-packages/urllib3/connection.py", line 157, in _new_conn
    (self._dns_host, self.port), self.timeout, **extra_kw
  File "/usr/local/lib/python3.7/site-packages/urllib3/util/connection.py", line 84, in create_connection
    raise err
  File "/usr/local/lib/python3.7/site-packages/urllib3/util/connection.py", line 74, in create_connection
    sock.connect(sa)
ConnectionRefusedError: [Errno 111] Connection refused

During handling of the above exception, another exception occurred:

Traceback (most recent call last):
  File "/usr/local/lib/python3.7/site-packages/elasticsearch/connection/http_urllib3.py", line 238, in perform_request
    method, url, body, retries=Retry(False), headers=request_headers, **kw
  File "/usr/local/lib/python3.7/site-packages/urllib3/connectionpool.py", line 720, in urlopen
    method, url, error=e, _pool=self, _stacktrace=sys.exc_info()[2]
  File "/usr/local/lib/python3.7/site-packages/urllib3/util/retry.py", line 376, in increment
    raise six.reraise(type(error), error, _stacktrace)
  File "/usr/local/lib/python3.7/site-packages/urllib3/packages/six.py", line 735, in reraise
    raise value
  File "/usr/local/lib/python3.7/site-packages/urllib3/connectionpool.py", line 672, in urlopen
    chunked=chunked,
  File "/usr/local/lib/python3.7/site-packages/urllib3/connectionpool.py", line 387, in _make_request
    conn.request(method, url, **httplib_request_kw)
  File "/usr/local/lib/python3.7/http/client.py", line 1252, in request
    self._send_request(method, url, body, headers, encode_chunked)
  File "/usr/local/lib/python3.7/http/client.py", line 1298, in _send_request
    self.endheaders(body, encode_chunked=encode_chunked)
  File "/usr/local/lib/python3.7/http/client.py", line 1247, in endheaders
    self._send_output(message_body, encode_chunked=encode_chunked)
  File "/usr/local/lib/python3.7/http/client.py", line 1026, in _send_output
    self.send(msg)
  File "/usr/local/lib/python3.7/http/client.py", line 966, in send
    self.connect()
  File "/usr/local/lib/python3.7/site-packages/urllib3/connection.py", line 184, in connect
    conn = self._new_conn()
  File "/usr/local/lib/python3.7/site-packages/urllib3/connection.py", line 169, in _new_conn
    self, "Failed to establish a new connection: %s" % e
urllib3.exceptions.NewConnectionError: <urllib3.connection.HTTPConnection object at 0x7efc24513790>: Failed to establish a new connection: [Errno 111] Connection refused
2019-12-12 03:51:27 [elasticsearch] DEBUG: > None
2019-12-12 03:51:27 [urllib3.connectionpool] DEBUG: Starting new HTTP connection (4): elasticsearch:9200
2019-12-12 03:51:27 [elasticsearch] WARNING: HEAD http://elasticsearch:9200/top [status:N/A request:0.005s]
Traceback (most recent call last):
  File "/usr/local/lib/python3.7/site-packages/urllib3/connection.py", line 157, in _new_conn
    (self._dns_host, self.port), self.timeout, **extra_kw
  File "/usr/local/lib/python3.7/site-packages/urllib3/util/connection.py", line 84, in create_connection
    raise err
  File "/usr/local/lib/python3.7/site-packages/urllib3/util/connection.py", line 74, in create_connection
    sock.connect(sa)
ConnectionRefusedError: [Errno 111] Connection refused

During handling of the above exception, another exception occurred:

Traceback (most recent call last):
  File "/usr/local/lib/python3.7/site-packages/elasticsearch/connection/http_urllib3.py", line 238, in perform_request
    method, url, body, retries=Retry(False), headers=request_headers, **kw
  File "/usr/local/lib/python3.7/site-packages/urllib3/connectionpool.py", line 720, in urlopen
    method, url, error=e, _pool=self, _stacktrace=sys.exc_info()[2]
  File "/usr/local/lib/python3.7/site-packages/urllib3/util/retry.py", line 376, in increment
    raise six.reraise(type(error), error, _stacktrace)
  File "/usr/local/lib/python3.7/site-packages/urllib3/packages/six.py", line 735, in reraise
    raise value
  File "/usr/local/lib/python3.7/site-packages/urllib3/connectionpool.py", line 672, in urlopen
    chunked=chunked,
  File "/usr/local/lib/python3.7/site-packages/urllib3/connectionpool.py", line 387, in _make_request
    conn.request(method, url, **httplib_request_kw)
  File "/usr/local/lib/python3.7/http/client.py", line 1252, in request
    self._send_request(method, url, body, headers, encode_chunked)
  File "/usr/local/lib/python3.7/http/client.py", line 1298, in _send_request
    self.endheaders(body, encode_chunked=encode_chunked)
  File "/usr/local/lib/python3.7/http/client.py", line 1247, in endheaders
    self._send_output(message_body, encode_chunked=encode_chunked)
  File "/usr/local/lib/python3.7/http/client.py", line 1026, in _send_output
    self.send(msg)
  File "/usr/local/lib/python3.7/http/client.py", line 966, in send
    self.connect()
  File "/usr/local/lib/python3.7/site-packages/urllib3/connection.py", line 184, in connect
    conn = self._new_conn()
  File "/usr/local/lib/python3.7/site-packages/urllib3/connection.py", line 169, in _new_conn
    self, "Failed to establish a new connection: %s" % e
urllib3.exceptions.NewConnectionError: <urllib3.connection.HTTPConnection object at 0x7efc2452d5d0>: Failed to establish a new connection: [Errno 111] Connection refused
2019-12-12 03:51:27 [elasticsearch] DEBUG: > None
2019-12-12 03:51:27 [elasticsearch] WARNING: HEAD http://elasticsearch:9200/top [status:N/A request:0.007s]
Traceback (most recent call last):
  File "/usr/local/lib/python3.7/site-packages/urllib3/connection.py", line 157, in _new_conn
    (self._dns_host, self.port), self.timeout, **extra_kw
  File "/usr/local/lib/python3.7/site-packages/urllib3/util/connection.py", line 84, in create_connection
    raise err
  File "/usr/local/lib/python3.7/site-packages/urllib3/util/connection.py", line 74, in create_connection
    sock.connect(sa)
ConnectionRefusedError: [Errno 111] Connection refused

During handling of the above exception, another exception occurred:

Traceback (most recent call last):
  File "/usr/local/lib/python3.7/site-packages/elasticsearch/connection/http_urllib3.py", line 238, in perform_request
    method, url, body, retries=Retry(False), headers=request_headers, **kw
  File "/usr/local/lib/python3.7/site-packages/urllib3/connectionpool.py", line 720, in urlopen
    method, url, error=e, _pool=self, _stacktrace=sys.exc_info()[2]
  File "/usr/local/lib/python3.7/site-packages/urllib3/util/retry.py", line 376, in increment
    raise six.reraise(type(error), error, _stacktrace)
  File "/usr/local/lib/python3.7/site-packages/urllib3/packages/six.py", line 735, in reraise
    raise value
  File "/usr/local/lib/python3.7/site-packages/urllib3/connectionpool.py", line 672, in urlopen
    chunked=chunked,
  File "/usr/local/lib/python3.7/site-packages/urllib3/connectionpool.py", line 387, in _make_request
    conn.request(method, url, **httplib_request_kw)
  File "/usr/local/lib/python3.7/http/client.py", line 1252, in request
    self._send_request(method, url, body, headers, encode_chunked)
  File "/usr/local/lib/python3.7/http/client.py", line 1298, in _send_request
    self.endheaders(body, encode_chunked=encode_chunked)
  File "/usr/local/lib/python3.7/http/client.py", line 1247, in endheaders
    self._send_output(message_body, encode_chunked=encode_chunked)
  File "/usr/local/lib/python3.7/http/client.py", line 1026, in _send_output
    self.send(msg)
  File "/usr/local/lib/python3.7/http/client.py", line 966, in send
    self.connect()
  File "/usr/local/lib/python3.7/site-packages/urllib3/connection.py", line 184, in connect
    conn = self._new_conn()
  File "/usr/local/lib/python3.7/site-packages/urllib3/connection.py", line 169, in _new_conn
    self, "Failed to establish a new connection: %s" % e
urllib3.exceptions.NewConnectionError: <urllib3.connection.HTTPConnection object at 0x7efc2452d2d0>: Failed to establish a new connection: [Errno 111] Connection refused
2019-12-12 03:51:27 [elasticsearch] DEBUG: > None
2019-12-12 03:51:27 [elasticsearch] WARNING: HEAD http://elasticsearch:9200/top [status:N/A request:0.006s]
Traceback (most recent call last):
  File "/usr/local/lib/python3.7/site-packages/urllib3/connection.py", line 157, in _new_conn
    (self._dns_host, self.port), self.timeout, **extra_kw
  File "/usr/local/lib/python3.7/site-packages/urllib3/util/connection.py", line 84, in create_connection
    raise err
  File "/usr/local/lib/python3.7/site-packages/urllib3/util/connection.py", line 74, in create_connection
    sock.connect(sa)
ConnectionRefusedError: [Errno 111] Connection refused

During handling of the above exception, another exception occurred:

Traceback (most recent call last):
  File "/usr/local/lib/python3.7/site-packages/elasticsearch/connection/http_urllib3.py", line 238, in perform_request
    method, url, body, retries=Retry(False), headers=request_headers, **kw
  File "/usr/local/lib/python3.7/site-packages/urllib3/connectionpool.py", line 720, in urlopen
    method, url, error=e, _pool=self, _stacktrace=sys.exc_info()[2]
  File "/usr/local/lib/python3.7/site-packages/urllib3/util/retry.py", line 376, in increment
    raise six.reraise(type(error), error, _stacktrace)
  File "/usr/local/lib/python3.7/site-packages/urllib3/packages/six.py", line 735, in reraise
    raise value
  File "/usr/local/lib/python3.7/site-packages/urllib3/connectionpool.py", line 672, in urlopen
    chunked=chunked,
  File "/usr/local/lib/python3.7/site-packages/urllib3/connectionpool.py", line 387, in _make_request
    conn.request(method, url, **httplib_request_kw)
  File "/usr/local/lib/python3.7/http/client.py", line 1252, in request
    self._send_request(method, url, body, headers, encode_chunked)
  File "/usr/local/lib/python3.7/http/client.py", line 1298, in _send_request
    self.endheaders(body, encode_chunked=encode_chunked)
  File "/usr/local/lib/python3.7/http/client.py", line 1247, in endheaders
    self._send_output(message_body, encode_chunked=encode_chunked)
  File "/usr/local/lib/python3.7/http/client.py", line 1026, in _send_output
    self.send(msg)
  File "/usr/local/lib/python3.7/http/client.py", line 966, in send
    self.connect()
  File "/usr/local/lib/python3.7/site-packages/urllib3/connection.py", line 184, in connect
    conn = self._new_conn()
  File "/usr/local/lib/python3.7/site-packages/urllib3/connection.py", line 169, in _new_conn
    self, "Failed to establish a new connection: %s" % e
urllib3.exceptions.NewConnectionError: <urllib3.connection.HTTPConnection object at 0x7efc2452d890>: Failed to establish a new connection: [Errno 111] Connection refused
2019-12-12 03:51:27 [elasticsearch] DEBUG: > None
2019-12-12 03:51:27 [elasticsearch] WARNING: HEAD http://elasticsearch:9200/top [status:N/A request:0.009s]
Traceback (most recent call last):
  File "/usr/local/lib/python3.7/site-packages/urllib3/connection.py", line 157, in _new_conn
    (self._dns_host, self.port), self.timeout, **extra_kw
  File "/usr/local/lib/python3.7/site-packages/urllib3/util/connection.py", line 84, in create_connection
    raise err
  File "/usr/local/lib/python3.7/site-packages/urllib3/util/connection.py", line 74, in create_connection
    sock.connect(sa)
ConnectionRefusedError: [Errno 111] Connection refused

During handling of the above exception, another exception occurred:

Traceback (most recent call last):
  File "/usr/local/lib/python3.7/site-packages/elasticsearch/connection/http_urllib3.py", line 238, in perform_request
    method, url, body, retries=Retry(False), headers=request_headers, **kw
  File "/usr/local/lib/python3.7/site-packages/urllib3/connectionpool.py", line 720, in urlopen
    method, url, error=e, _pool=self, _stacktrace=sys.exc_info()[2]
  File "/usr/local/lib/python3.7/site-packages/urllib3/util/retry.py", line 376, in increment
    raise six.reraise(type(error), error, _stacktrace)
  File "/usr/local/lib/python3.7/site-packages/urllib3/packages/six.py", line 735, in reraise
    raise value
  File "/usr/local/lib/python3.7/site-packages/urllib3/connectionpool.py", line 672, in urlopen
    chunked=chunked,
  File "/usr/local/lib/python3.7/site-packages/urllib3/connectionpool.py", line 387, in _make_request
    conn.request(method, url, **httplib_request_kw)
  File "/usr/local/lib/python3.7/http/client.py", line 1252, in request
    self._send_request(method, url, body, headers, encode_chunked)
  File "/usr/local/lib/python3.7/http/client.py", line 1298, in _send_request
    self.endheaders(body, encode_chunked=encode_chunked)
  File "/usr/local/lib/python3.7/http/client.py", line 1247, in endheaders
    self._send_output(message_body, encode_chunked=encode_chunked)
  File "/usr/local/lib/python3.7/http/client.py", line 1026, in _send_output
    self.send(msg)
  File "/usr/local/lib/python3.7/http/client.py", line 966, in send
    self.connect()
  File "/usr/local/lib/python3.7/site-packages/urllib3/connection.py", line 184, in connect
    conn = self._new_conn()
  File "/usr/local/lib/python3.7/site-packages/urllib3/connection.py", line 169, in _new_conn
    self, "Failed to establish a new connection: %s" % e
urllib3.exceptions.NewConnectionError: <urllib3.connection.HTTPConnection object at 0x7efc24513450>: Failed to establish a new connection: [Errno 111] Connection refused
2019-12-12 03:51:27 [elasticsearch] DEBUG: > None
2019-12-12 03:51:27 [urllib3.connectionpool] DEBUG: Starting new HTTP connection (1): elasticsearch:9200
2019-12-12 03:51:27 [elasticsearch] WARNING: HEAD http://elasticsearch:9200/top [status:N/A request:0.005s]
Traceback (most recent call last):
  File "/usr/local/lib/python3.7/site-packages/urllib3/connection.py", line 157, in _new_conn
    (self._dns_host, self.port), self.timeout, **extra_kw
  File "/usr/local/lib/python3.7/site-packages/urllib3/util/connection.py", line 84, in create_connection
    raise err
  File "/usr/local/lib/python3.7/site-packages/urllib3/util/connection.py", line 74, in create_connection
    sock.connect(sa)
ConnectionRefusedError: [Errno 111] Connection refused

During handling of the above exception, another exception occurred:

Traceback (most recent call last):
  File "/usr/local/lib/python3.7/site-packages/elasticsearch/connection/http_urllib3.py", line 238, in perform_request
    method, url, body, retries=Retry(False), headers=request_headers, **kw
  File "/usr/local/lib/python3.7/site-packages/urllib3/connectionpool.py", line 720, in urlopen
    method, url, error=e, _pool=self, _stacktrace=sys.exc_info()[2]
  File "/usr/local/lib/python3.7/site-packages/urllib3/util/retry.py", line 376, in increment
    raise six.reraise(type(error), error, _stacktrace)
  File "/usr/local/lib/python3.7/site-packages/urllib3/packages/six.py", line 735, in reraise
    raise value
  File "/usr/local/lib/python3.7/site-packages/urllib3/connectionpool.py", line 672, in urlopen
    chunked=chunked,
  File "/usr/local/lib/python3.7/site-packages/urllib3/connectionpool.py", line 387, in _make_request
    conn.request(method, url, **httplib_request_kw)
  File "/usr/local/lib/python3.7/http/client.py", line 1252, in request
    self._send_request(method, url, body, headers, encode_chunked)
  File "/usr/local/lib/python3.7/http/client.py", line 1298, in _send_request
    self.endheaders(body, encode_chunked=encode_chunked)
  File "/usr/local/lib/python3.7/http/client.py", line 1247, in endheaders
    self._send_output(message_body, encode_chunked=encode_chunked)
  File "/usr/local/lib/python3.7/http/client.py", line 1026, in _send_output
    self.send(msg)
  File "/usr/local/lib/python3.7/http/client.py", line 966, in send
    self.connect()
  File "/usr/local/lib/python3.7/site-packages/urllib3/connection.py", line 184, in connect
    conn = self._new_conn()
  File "/usr/local/lib/python3.7/site-packages/urllib3/connection.py", line 169, in _new_conn
    self, "Failed to establish a new connection: %s" % e
urllib3.exceptions.NewConnectionError: <urllib3.connection.HTTPConnection object at 0x7efc24580110>: Failed to establish a new connection: [Errno 111] Connection refused
2019-12-12 03:51:27 [elasticsearch] DEBUG: > None
2019-12-12 03:51:27 [urllib3.connectionpool] DEBUG: Starting new HTTP connection (2): elasticsearch:9200
2019-12-12 03:51:27 [elasticsearch] WARNING: HEAD http://elasticsearch:9200/top [status:N/A request:0.005s]
Traceback (most recent call last):
  File "/usr/local/lib/python3.7/site-packages/urllib3/connection.py", line 157, in _new_conn
    (self._dns_host, self.port), self.timeout, **extra_kw
  File "/usr/local/lib/python3.7/site-packages/urllib3/util/connection.py", line 84, in create_connection
    raise err
  File "/usr/local/lib/python3.7/site-packages/urllib3/util/connection.py", line 74, in create_connection
    sock.connect(sa)
ConnectionRefusedError: [Errno 111] Connection refused

During handling of the above exception, another exception occurred:

Traceback (most recent call last):
  File "/usr/local/lib/python3.7/site-packages/elasticsearch/connection/http_urllib3.py", line 238, in perform_request
    method, url, body, retries=Retry(False), headers=request_headers, **kw
  File "/usr/local/lib/python3.7/site-packages/urllib3/connectionpool.py", line 720, in urlopen
    method, url, error=e, _pool=self, _stacktrace=sys.exc_info()[2]
  File "/usr/local/lib/python3.7/site-packages/urllib3/util/retry.py", line 376, in increment
    raise six.reraise(type(error), error, _stacktrace)
  File "/usr/local/lib/python3.7/site-packages/urllib3/packages/six.py", line 735, in reraise
    raise value
  File "/usr/local/lib/python3.7/site-packages/urllib3/connectionpool.py", line 672, in urlopen
    chunked=chunked,
  File "/usr/local/lib/python3.7/site-packages/urllib3/connectionpool.py", line 387, in _make_request
    conn.request(method, url, **httplib_request_kw)
  File "/usr/local/lib/python3.7/http/client.py", line 1252, in request
    self._send_request(method, url, body, headers, encode_chunked)
  File "/usr/local/lib/python3.7/http/client.py", line 1298, in _send_request
    self.endheaders(body, encode_chunked=encode_chunked)
  File "/usr/local/lib/python3.7/http/client.py", line 1247, in endheaders
    self._send_output(message_body, encode_chunked=encode_chunked)
  File "/usr/local/lib/python3.7/http/client.py", line 1026, in _send_output
    self.send(msg)
  File "/usr/local/lib/python3.7/http/client.py", line 966, in send
    self.connect()
  File "/usr/local/lib/python3.7/site-packages/urllib3/connection.py", line 184, in connect
    conn = self._new_conn()
  File "/usr/local/lib/python3.7/site-packages/urllib3/connection.py", line 169, in _new_conn
    self, "Failed to establish a new connection: %s" % e
urllib3.exceptions.NewConnectionError: <urllib3.connection.HTTPConnection object at 0x7efc245134d0>: Failed to establish a new connection: [Errno 111] Connection refused
2019-12-12 03:51:27 [elasticsearch] DEBUG: > None
2019-12-12 03:51:27 [urllib3.connectionpool] DEBUG: Starting new HTTP connection (3): elasticsearch:9200
2019-12-12 03:51:27 [urllib3.connectionpool] DEBUG: Starting new HTTP connection (1): elasticsearch:9200
2019-12-12 03:51:27 [urllib3.connectionpool] DEBUG: Starting new HTTP connection (1): elasticsearch:9200
2019-12-12 03:51:27 [urllib3.connectionpool] DEBUG: Starting new HTTP connection (1): elasticsearch:9200
2019-12-12 03:51:27 [urllib3.connectionpool] DEBUG: Starting new HTTP connection (1): elasticsearch:9200
2019-12-12 03:51:28 [urllib3.connectionpool] DEBUG: http://elasticsearch:9200 "HEAD /top HTTP/1.1" 404 0
2019-12-12 03:51:28 [urllib3.connectionpool] DEBUG: http://elasticsearch:9200 "HEAD /top HTTP/1.1" 404 0
2019-12-12 03:51:28 [urllib3.connectionpool] DEBUG: http://elasticsearch:9200 "HEAD /top HTTP/1.1" 404 0
2019-12-12 03:51:28 [urllib3.connectionpool] DEBUG: http://elasticsearch:9200 "HEAD /top HTTP/1.1" 404 0
2019-12-12 03:51:28 [urllib3.connectionpool] DEBUG: http://elasticsearch:9200 "HEAD /top HTTP/1.1" 404 0
2019-12-12 03:51:28 [urllib3.connectionpool] DEBUG: http://elasticsearch:9200 "PUT /top HTTP/1.1" 400 353
2019-12-12 03:51:28 [elasticsearch] INFO: PUT http://elasticsearch:9200/top [status:400 request:0.671s]
2019-12-12 03:51:28 [elasticsearch] DEBUG: > None
2019-12-12 03:51:28 [elasticsearch] DEBUG: < {"error":{"root_cause":[{"type":"resource_already_exists_exception","reason":"index [top/MlVKThQVRYCt58QKJbwj2g] already exists","index_uuid":"MlVKThQVRYCt58QKJbwj2g","index":"top"}],"type":"resource_already_exists_exception","reason":"index [top/MlVKThQVRYCt58QKJbwj2g] already exists","index_uuid":"MlVKThQVRYCt58QKJbwj2g","index":"top"},"status":400}
2019-12-12 03:51:28 [urllib3.connectionpool] DEBUG: http://elasticsearch:9200 "PUT /top HTTP/1.1" 400 353
2019-12-12 03:51:28 [elasticsearch] INFO: PUT http://elasticsearch:9200/top [status:400 request:0.662s]
2019-12-12 03:51:28 [elasticsearch] DEBUG: > None
2019-12-12 03:51:28 [elasticsearch] DEBUG: < {"error":{"root_cause":[{"type":"resource_already_exists_exception","reason":"index [top/MlVKThQVRYCt58QKJbwj2g] already exists","index_uuid":"MlVKThQVRYCt58QKJbwj2g","index":"top"}],"type":"resource_already_exists_exception","reason":"index [top/MlVKThQVRYCt58QKJbwj2g] already exists","index_uuid":"MlVKThQVRYCt58QKJbwj2g","index":"top"},"status":400}
2019-12-12 03:51:28 [urllib3.connectionpool] DEBUG: http://elasticsearch:9200 "PUT /top HTTP/1.1" 400 353
2019-12-12 03:51:28 [elasticsearch] INFO: PUT http://elasticsearch:9200/top [status:400 request:0.687s]
2019-12-12 03:51:28 [elasticsearch] DEBUG: > None
2019-12-12 03:51:28 [elasticsearch] DEBUG: < {"error":{"root_cause":[{"type":"resource_already_exists_exception","reason":"index [top/MlVKThQVRYCt58QKJbwj2g] already exists","index_uuid":"MlVKThQVRYCt58QKJbwj2g","index":"top"}],"type":"resource_already_exists_exception","reason":"index [top/MlVKThQVRYCt58QKJbwj2g] already exists","index_uuid":"MlVKThQVRYCt58QKJbwj2g","index":"top"},"status":400}
2019-12-12 03:51:28 [urllib3.connectionpool] DEBUG: http://elasticsearch:9200 "PUT /top HTTP/1.1" 400 353
2019-12-12 03:51:28 [elasticsearch] INFO: PUT http://elasticsearch:9200/top [status:400 request:0.674s]
2019-12-12 03:51:28 [elasticsearch] DEBUG: > None
2019-12-12 03:51:28 [elasticsearch] DEBUG: < {"error":{"root_cause":[{"type":"resource_already_exists_exception","reason":"index [top/MlVKThQVRYCt58QKJbwj2g] already exists","index_uuid":"MlVKThQVRYCt58QKJbwj2g","index":"top"}],"type":"resource_already_exists_exception","reason":"index [top/MlVKThQVRYCt58QKJbwj2g] already exists","index_uuid":"MlVKThQVRYCt58QKJbwj2g","index":"top"},"status":400}
2019-12-12 03:51:28 [urllib3.connectionpool] DEBUG: http://elasticsearch:9200 "PUT /top HTTP/1.1" 400 353
2019-12-12 03:51:28 [elasticsearch] INFO: PUT http://elasticsearch:9200/top [status:400 request:0.708s]
2019-12-12 03:51:28 [elasticsearch] DEBUG: > None
2019-12-12 03:51:28 [elasticsearch] DEBUG: < {"error":{"root_cause":[{"type":"resource_already_exists_exception","reason":"index [top/MlVKThQVRYCt58QKJbwj2g] already exists","index_uuid":"MlVKThQVRYCt58QKJbwj2g","index":"top"}],"type":"resource_already_exists_exception","reason":"index [top/MlVKThQVRYCt58QKJbwj2g] already exists","index_uuid":"MlVKThQVRYCt58QKJbwj2g","index":"top"},"status":400}
2019-12-12 03:51:31 [urllib3.connectionpool] DEBUG: http://elasticsearch:9200 "PUT /top/_mapping HTTP/1.1" 400 723
2019-12-12 03:51:31 [elasticsearch] WARNING: PUT http://elasticsearch:9200/top/_mapping [status:400 request:2.168s]
2019-12-12 03:51:31 [elasticsearch] DEBUG: > {"top":{"properties":{"title":{"type":"text","analyzer":"ik_max_word","search_analyzer":"ik_smart"},"description_content":{"type":"string","analyzer":"ik_max_word","search_analyzer":"ik_smart"},"update_at":{"type":"long","analyzer":"ik_max_word","search_analyzer":"ik_smart"}}}}
2019-12-12 03:51:31 [elasticsearch] DEBUG: < {"error":{"root_cause":[{"type":"mapper_parsing_exception","reason":"Root mapping definition has unsupported parameters:  [top : {properties={description_content={search_analyzer=ik_smart, analyzer=ik_max_word, type=string}, update_at={search_analyzer=ik_smart, analyzer=ik_max_word, type=long}, title={search_analyzer=ik_smart, analyzer=ik_max_word, type=text}}}]"}],"type":"mapper_parsing_exception","reason":"Root mapping definition has unsupported parameters:  [top : {properties={description_content={search_analyzer=ik_smart, analyzer=ik_max_word, type=string}, update_at={search_analyzer=ik_smart, analyzer=ik_max_word, type=long}, title={search_analyzer=ik_smart, analyzer=ik_max_word, type=text}}}]"},"status":400}
2019-12-12 03:51:31 [urllib3.connectionpool] DEBUG: Starting new HTTP connection (1): elasticsearch:9200
2019-12-12 03:51:31 [urllib3.connectionpool] DEBUG: http://elasticsearch:9200 "PUT /top/_mapping HTTP/1.1" 400 723
2019-12-12 03:51:31 [elasticsearch] WARNING: PUT http://elasticsearch:9200/top/_mapping [status:400 request:2.166s]
2019-12-12 03:51:31 [elasticsearch] DEBUG: > {"top":{"properties":{"title":{"type":"text","analyzer":"ik_max_word","search_analyzer":"ik_smart"},"description_content":{"type":"string","analyzer":"ik_max_word","search_analyzer":"ik_smart"},"update_at":{"type":"long","analyzer":"ik_max_word","search_analyzer":"ik_smart"}}}}
2019-12-12 03:51:31 [elasticsearch] DEBUG: < {"error":{"root_cause":[{"type":"mapper_parsing_exception","reason":"Root mapping definition has unsupported parameters:  [top : {properties={description_content={search_analyzer=ik_smart, analyzer=ik_max_word, type=string}, update_at={search_analyzer=ik_smart, analyzer=ik_max_word, type=long}, title={search_analyzer=ik_smart, analyzer=ik_max_word, type=text}}}]"}],"type":"mapper_parsing_exception","reason":"Root mapping definition has unsupported parameters:  [top : {properties={description_content={search_analyzer=ik_smart, analyzer=ik_max_word, type=string}, update_at={search_analyzer=ik_smart, analyzer=ik_max_word, type=long}, title={search_analyzer=ik_smart, analyzer=ik_max_word, type=text}}}]"},"status":400}
2019-12-12 03:51:31 [urllib3.connectionpool] DEBUG: http://elasticsearch:9200 "HEAD /top HTTP/1.1" 200 0
2019-12-12 03:51:31 [elasticsearch] INFO: HEAD http://elasticsearch:9200/top [status:200 request:0.024s]
2019-12-12 03:51:31 [elasticsearch] DEBUG: > None
2019-12-12 03:51:31 [elasticsearch] DEBUG: < 
2019-12-12 03:51:31 [urllib3.connectionpool] DEBUG: Starting new HTTP connection (1): elasticsearch:9200
2019-12-12 03:51:31 [urllib3.connectionpool] DEBUG: http://elasticsearch:9200 "PUT /top/_mapping HTTP/1.1" 400 723
2019-12-12 03:51:31 [elasticsearch] WARNING: PUT http://elasticsearch:9200/top/_mapping [status:400 request:2.236s]
2019-12-12 03:51:31 [elasticsearch] DEBUG: > {"top":{"properties":{"title":{"type":"text","analyzer":"ik_max_word","search_analyzer":"ik_smart"},"description_content":{"type":"string","analyzer":"ik_max_word","search_analyzer":"ik_smart"},"update_at":{"type":"long","analyzer":"ik_max_word","search_analyzer":"ik_smart"}}}}
2019-12-12 03:51:31 [elasticsearch] DEBUG: < {"error":{"root_cause":[{"type":"mapper_parsing_exception","reason":"Root mapping definition has unsupported parameters:  [top : {properties={description_content={search_analyzer=ik_smart, analyzer=ik_max_word, type=string}, update_at={search_analyzer=ik_smart, analyzer=ik_max_word, type=long}, title={search_analyzer=ik_smart, analyzer=ik_max_word, type=text}}}]"}],"type":"mapper_parsing_exception","reason":"Root mapping definition has unsupported parameters:  [top : {properties={description_content={search_analyzer=ik_smart, analyzer=ik_max_word, type=string}, update_at={search_analyzer=ik_smart, analyzer=ik_max_word, type=long}, title={search_analyzer=ik_smart, analyzer=ik_max_word, type=text}}}]"},"status":400}
2019-12-12 03:51:31 [urllib3.connectionpool] DEBUG: http://elasticsearch:9200 "PUT /top/_mapping HTTP/1.1" 400 723
2019-12-12 03:51:31 [elasticsearch] WARNING: PUT http://elasticsearch:9200/top/_mapping [status:400 request:2.262s]
2019-12-12 03:51:31 [elasticsearch] DEBUG: > {"top":{"properties":{"title":{"type":"text","analyzer":"ik_max_word","search_analyzer":"ik_smart"},"description_content":{"type":"string","analyzer":"ik_max_word","search_analyzer":"ik_smart"},"update_at":{"type":"long","analyzer":"ik_max_word","search_analyzer":"ik_smart"}}}}
2019-12-12 03:51:31 [elasticsearch] DEBUG: < {"error":{"root_cause":[{"type":"mapper_parsing_exception","reason":"Root mapping definition has unsupported parameters:  [top : {properties={description_content={search_analyzer=ik_smart, analyzer=ik_max_word, type=string}, update_at={search_analyzer=ik_smart, analyzer=ik_max_word, type=long}, title={search_analyzer=ik_smart, analyzer=ik_max_word, type=text}}}]"}],"type":"mapper_parsing_exception","reason":"Root mapping definition has unsupported parameters:  [top : {properties={description_content={search_analyzer=ik_smart, analyzer=ik_max_word, type=string}, update_at={search_analyzer=ik_smart, analyzer=ik_max_word, type=long}, title={search_analyzer=ik_smart, analyzer=ik_max_word, type=text}}}]"},"status":400}
2019-12-12 03:51:31 [urllib3.connectionpool] DEBUG: Starting new HTTP connection (1): elasticsearch:9200
2019-12-12 03:51:31 [urllib3.connectionpool] DEBUG: Starting new HTTP connection (1): elasticsearch:9200
2019-12-12 03:51:31 [urllib3.connectionpool] DEBUG: http://elasticsearch:9200 "PUT /top/_mapping HTTP/1.1" 400 723
2019-12-12 03:51:31 [elasticsearch] WARNING: PUT http://elasticsearch:9200/top/_mapping [status:400 request:2.216s]
2019-12-12 03:51:31 [elasticsearch] DEBUG: > {"top":{"properties":{"title":{"type":"text","analyzer":"ik_max_word","search_analyzer":"ik_smart"},"description_content":{"type":"string","analyzer":"ik_max_word","search_analyzer":"ik_smart"},"update_at":{"type":"long","analyzer":"ik_max_word","search_analyzer":"ik_smart"}}}}
2019-12-12 03:51:31 [elasticsearch] DEBUG: < {"error":{"root_cause":[{"type":"mapper_parsing_exception","reason":"Root mapping definition has unsupported parameters:  [top : {properties={description_content={search_analyzer=ik_smart, analyzer=ik_max_word, type=string}, update_at={search_analyzer=ik_smart, analyzer=ik_max_word, type=long}, title={search_analyzer=ik_smart, analyzer=ik_max_word, type=text}}}]"}],"type":"mapper_parsing_exception","reason":"Root mapping definition has unsupported parameters:  [top : {properties={description_content={search_analyzer=ik_smart, analyzer=ik_max_word, type=string}, update_at={search_analyzer=ik_smart, analyzer=ik_max_word, type=long}, title={search_analyzer=ik_smart, analyzer=ik_max_word, type=text}}}]"},"status":400}
2019-12-12 03:51:31 [urllib3.connectionpool] DEBUG: Starting new HTTP connection (1): elasticsearch:9200
2019-12-12 03:51:31 [urllib3.connectionpool] DEBUG: http://elasticsearch:9200 "HEAD /top HTTP/1.1" 200 0
2019-12-12 03:51:31 [elasticsearch] INFO: HEAD http://elasticsearch:9200/top [status:200 request:0.243s]
2019-12-12 03:51:31 [elasticsearch] DEBUG: > None
2019-12-12 03:51:31 [elasticsearch] DEBUG: < 
2019-12-12 03:51:31 [urllib3.connectionpool] DEBUG: http://elasticsearch:9200 "HEAD /top HTTP/1.1" 200 0
2019-12-12 03:51:31 [elasticsearch] INFO: HEAD http://elasticsearch:9200/top [status:200 request:0.241s]
2019-12-12 03:51:31 [elasticsearch] DEBUG: > None
2019-12-12 03:51:31 [elasticsearch] DEBUG: < 
2019-12-12 03:51:31 [urllib3.connectionpool] DEBUG: http://elasticsearch:9200 "HEAD /top HTTP/1.1" 200 0
2019-12-12 03:51:31 [elasticsearch] INFO: HEAD http://elasticsearch:9200/top [status:200 request:0.225s]
2019-12-12 03:51:31 [elasticsearch] DEBUG: > None
2019-12-12 03:51:31 [elasticsearch] DEBUG: < 
2019-12-12 03:51:31 [urllib3.connectionpool] DEBUG: http://elasticsearch:9200 "HEAD /top HTTP/1.1" 200 0
2019-12-12 03:51:31 [elasticsearch] INFO: HEAD http://elasticsearch:9200/top [status:200 request:0.253s]
2019-12-12 03:51:31 [elasticsearch] DEBUG: > None
2019-12-12 03:51:31 [elasticsearch] DEBUG: < 
2019-12-12 03:51:32 [urllib3.connectionpool] DEBUG: http://elasticsearch:9200 "POST /top/_doc/1568 HTTP/1.1" 201 158
2019-12-12 03:51:32 [elasticsearch] INFO: POST http://elasticsearch:9200/top/_doc/1568 [status:201 request:1.210s]
2019-12-12 03:51:32 [elasticsearch] DEBUG: > {"title":"16″ MacBook Pro 体验：也许不是最大的更新，但应该是这几年来最「对」的一次更新","description_content":"nerd_du","update_at":1576122687578}
2019-12-12 03:51:32 [elasticsearch] DEBUG: < {"_index":"top","_type":"_doc","_id":"1568","_version":1,"result":"created","_shards":{"total":2,"successful":1,"failed":0},"_seq_no":2073,"_primary_term":14}
2019-12-12 03:51:32 [urllib3.connectionpool] DEBUG: http://elasticsearch:9200 "POST /top/_doc/1571 HTTP/1.1" 201 158
2019-12-12 03:51:32 [elasticsearch] INFO: POST http://elasticsearch:9200/top/_doc/1571 [status:201 request:0.920s]
2019-12-12 03:51:32 [elasticsearch] DEBUG: > {"title":"iWork 不为人知的功能——以苹果返校活动宣传图的实现为例","description_content":"HarveyJanson","update_at":1576122687578}
2019-12-12 03:51:32 [elasticsearch] DEBUG: < {"_index":"top","_type":"_doc","_id":"1571","_version":1,"result":"created","_shards":{"total":2,"successful":1,"failed":0},"_seq_no":2074,"_primary_term":14}
2019-12-12 03:51:32 [urllib3.connectionpool] DEBUG: http://elasticsearch:9200 "POST /top/_doc/1569 HTTP/1.1" 201 158
2019-12-12 03:51:32 [elasticsearch] INFO: POST http://elasticsearch:9200/top/_doc/1569 [status:201 request:1.037s]
2019-12-12 03:51:32 [elasticsearch] DEBUG: > {"title":"两种方法，让 Windows 10 也能自动切换深/浅色主题","description_content":"化学心情下2","update_at":1576122687578}
2019-12-12 03:51:32 [elasticsearch] DEBUG: < {"_index":"top","_type":"_doc","_id":"1569","_version":1,"result":"created","_shards":{"total":2,"successful":1,"failed":0},"_seq_no":2076,"_primary_term":14}
2019-12-12 03:51:32 [urllib3.connectionpool] DEBUG: http://elasticsearch:9200 "POST /top/_doc/1570 HTTP/1.1" 201 158
2019-12-12 03:51:32 [elasticsearch] INFO: POST http://elasticsearch:9200/top/_doc/1570 [status:201 request:1.048s]
2019-12-12 03:51:32 [elasticsearch] DEBUG: > {"title":"5 年来首次大版本更新，iOS 第三方微博客户端「墨客」推新版","description_content":"waychane","update_at":1576122687578}
2019-12-12 03:51:32 [elasticsearch] DEBUG: < {"_index":"top","_type":"_doc","_id":"1570","_version":1,"result":"created","_shards":{"total":2,"successful":1,"failed":0},"_seq_no":2077,"_primary_term":14}
2019-12-12 03:51:32 [urllib3.connectionpool] DEBUG: http://elasticsearch:9200 "POST /top/_doc/1572 HTTP/1.1" 201 158
2019-12-12 03:51:32 [elasticsearch] INFO: POST http://elasticsearch:9200/top/_doc/1572 [status:201 request:1.149s]
2019-12-12 03:51:32 [elasticsearch] DEBUG: > {"title":"「黑五」硬件打折：这些数码产品值得买","description_content":"Vanilla","update_at":1576122687578}
2019-12-12 03:51:32 [elasticsearch] DEBUG: < {"_index":"top","_type":"_doc","_id":"1572","_version":1,"result":"created","_shards":{"total":2,"successful":1,"failed":0},"_seq_no":2080,"_primary_term":14}
